2022-01-23 16:34:18,886  ERROR pymapmanager.logger  logger.py handle_exception() line:87 -- Uncaught exception
Traceback (most recent call last):
  File "pymapmanager/stack.py", line 6, in <module>
    logger = logger.get_logger(__name__)
NameError: name 'logger' is not defined
2022-01-23 16:40:06,751   INFO __main__  stack.py _makeFolder() line:43 -- Base name folder already exists at /media/cudmore/data/richard/rr30a/stacks/rr30a_s0
2022-01-23 17:07:08,999  ERROR pymapmanager.logger  logger.py handle_exception() line:88 -- Uncaught exception
Traceback (most recent call last):
  File "pymapmanager/stack.py", line 140, in <module>
    myStack.loadImages(channel=1)
  File "pymapmanager/stack.py", line 58, in loadImages
    self._images[channelIdx] = tifffile(tifPath)
TypeError: 'module' object is not callable
2022-01-23 17:07:27,194  ERROR pymapmanager.logger  logger.py handle_exception() line:88 -- Uncaught exception
Traceback (most recent call last):
  File "pymapmanager/stack.py", line 140, in <module>
    myStack.loadImages(channel=1)
  File "pymapmanager/stack.py", line 58, in loadImages
    self._images[channelIdx] = tifffile.tifffile(tifPath)
TypeError: 'module' object is not callable
2022-01-23 17:08:27,661  ERROR pymapmanager.logger  logger.py handle_exception() line:88 -- Uncaught exception
Traceback (most recent call last):
  File "pymapmanager/stack.py", line 141, in <module>
    print('rows:', myStack.numImageRows)
  File "pymapmanager/stack.py", line 78, in numImageRows
    numRows = self._images[channel].shape[self.imageRowIdx]
AttributeError: 'stack' object has no attribute 'imageRowIdx'
2022-01-23 17:09:22,098  ERROR pymapmanager.logger  logger.py handle_exception() line:88 -- Uncaught exception
Traceback (most recent call last):
  File "pymapmanager/stack.py", line 142, in <module>
    print('rows:', myStack.numImageRows)
  File "pymapmanager/stack.py", line 79, in numImageRows
    numRows = self._images[channel].shape[self.imageRowIdx]
AttributeError: 'stack' object has no attribute 'imageRowIdx'
2022-01-23 17:42:04,931  ERROR pymapmanager.logger  logger.py handle_exception() line:88 -- Uncaught exception
Traceback (most recent call last):
  File "pymapmanager/lineAnnotations.py", line 44, in <module>
    la = lineAnnotations(stackBasePath)
  File "pymapmanager/lineAnnotations.py", line 14, in __init__
    self.load()
  File "pymapmanager/lineAnnotations.py", line 27, in load
    with open(lineFile, 'r') as f:
NameError: name 'lineFile' is not defined
2022-01-23 17:42:34,692  ERROR pymapmanager.logger  logger.py handle_exception() line:88 -- Uncaught exception
Traceback (most recent call last):
  File "pymapmanager/lineAnnotations.py", line 44, in <module>
    la = lineAnnotations(stackBasePath)
  File "pymapmanager/lineAnnotations.py", line 14, in __init__
    self.load()
  File "pymapmanager/lineAnnotations.py", line 40, in load
    self.linedb = pd.read_csv(lineFile, header=startReadingRow, index_col=False)
NameError: name 'lineFile' is not defined
2022-01-23 17:57:00,871  ERROR pymapmanager.logger  logger.py handle_exception() line:88 -- Uncaught exception
Traceback (most recent call last):
  File "pymapmanager/stack.py", line 190, in <module>
    myStack = stack(tifPath)
  File "pymapmanager/stack.py", line 59, in __init__
    self.loadLines()
  File "pymapmanager/stack.py", line 154, in loadLines
    self._lines = pymapmanager.lineAnnotations(self._getBaseName)
TypeError: 'module' object is not callable
2022-01-23 17:57:22,174  ERROR pymapmanager.logger  logger.py handle_exception() line:88 -- Uncaught exception
Traceback (most recent call last):
  File "pymapmanager/stack.py", line 190, in <module>
    myStack = stack(tifPath)
  File "pymapmanager/stack.py", line 59, in __init__
    self.loadLines()
  File "pymapmanager/stack.py", line 154, in loadLines
    self._lines = pymapmanager.lineAnnotations.lineAnnotations(self._getBaseName)
  File "/home/cudmore/Sites/PyMapManager/pymapmanager/lineAnnotations.py", line 20, in __init__
    self.load()
  File "/home/cudmore/Sites/PyMapManager/pymapmanager/lineAnnotations.py", line 29, in load
    linePath = self._getLinePath()
  File "/home/cudmore/Sites/PyMapManager/pymapmanager/lineAnnotations.py", line 23, in _getLinePath
    baseFolderName = os.path.split(self._stackBasePath)[1]
  File "/home/cudmore/anaconda3/lib/python3.8/posixpath.py", line 103, in split
    p = os.fspath(p)
TypeError: expected str, bytes or os.PathLike object, not method
2022-01-23 18:37:14,265  ERROR __main__  pointAnnotations.py load() line:29 -- Did not find annotation file /media/cudmore/data/richard/rr30a/stacks/rr30a_s0/rr30a_s0_db.txt
2022-01-23 18:37:14,265  ERROR pymapmanager.logger  logger.py handle_exception() line:88 -- Uncaught exception
Traceback (most recent call last):
  File "pymapmanager/pointAnnotations.py", line 62, in <module>
    print(xyz.shape)  # unlike .tif image, order is (x, y, slice)
AttributeError: 'NoneType' object has no attribute 'shape'
2022-01-23 18:42:45,520  ERROR pymapmanager.logger  logger.py handle_exception() line:88 -- Uncaught exception
Traceback (most recent call last):
  File "pymapmanager/pointAnnotations.py", line 66, in <module>
    la = pointAnnotations(stackBasePath)
  File "pymapmanager/pointAnnotations.py", line 15, in __init__
    self.load()
  File "pymapmanager/pointAnnotations.py", line 35, in load
    for key, value in items.split('='):
ValueError: too many values to unpack (expected 2)
2022-01-23 18:42:59,571  ERROR pymapmanager.logger  logger.py handle_exception() line:88 -- Uncaught exception
Traceback (most recent call last):
  File "pymapmanager/pointAnnotations.py", line 67, in <module>
    la = pointAnnotations(stackBasePath)
  File "pymapmanager/pointAnnotations.py", line 15, in __init__
    self.load()
  File "pymapmanager/pointAnnotations.py", line 36, in load
    for key, value in items.split('='):
ValueError: too many values to unpack (expected 2)
2022-01-23 18:43:20,183  ERROR pymapmanager.logger  logger.py handle_exception() line:88 -- Uncaught exception
Traceback (most recent call last):
  File "pymapmanager/pointAnnotations.py", line 68, in <module>
    la = pointAnnotations(stackBasePath)
  File "pymapmanager/pointAnnotations.py", line 15, in __init__
    self.load()
  File "pymapmanager/pointAnnotations.py", line 37, in load
    for key, value in items.split('='):
ValueError: too many values to unpack (expected 2)
2022-01-23 18:44:36,476  ERROR pymapmanager.logger  logger.py handle_exception() line:88 -- Uncaught exception
Traceback (most recent call last):
  File "pymapmanager/pointAnnotations.py", line 68, in <module>
    la = pointAnnotations(stackBasePath)
  File "pymapmanager/pointAnnotations.py", line 15, in __init__
    self.load()
  File "pymapmanager/pointAnnotations.py", line 37, in load
    for key, value in item.split('='):
ValueError: too many values to unpack (expected 2)
2022-01-23 18:45:45,711  ERROR pymapmanager.logger  logger.py handle_exception() line:88 -- Uncaught exception
Traceback (most recent call last):
  File "pymapmanager/pointAnnotations.py", line 70, in <module>
    la = pointAnnotations(stackBasePath)
  File "pymapmanager/pointAnnotations.py", line 15, in __init__
    self.load()
  File "pymapmanager/pointAnnotations.py", line 39, in load
    value = oneItem[1]
IndexError: string index out of range
2022-01-23 18:46:39,146  ERROR pymapmanager.logger  logger.py handle_exception() line:88 -- Uncaught exception
Traceback (most recent call last):
  File "pymapmanager/pointAnnotations.py", line 71, in <module>
    la = pointAnnotations(stackBasePath)
  File "pymapmanager/pointAnnotations.py", line 15, in __init__
    self.load()
  File "pymapmanager/pointAnnotations.py", line 40, in load
    value = oneItem[1]
IndexError: string index out of range
2022-01-23 18:47:03,956  ERROR pymapmanager.logger  logger.py handle_exception() line:88 -- Uncaught exception
Traceback (most recent call last):
  File "pymapmanager/pointAnnotations.py", line 71, in <module>
    la = pointAnnotations(stackBasePath)
  File "pymapmanager/pointAnnotations.py", line 15, in __init__
    self.load()
  File "pymapmanager/pointAnnotations.py", line 40, in load
    value = oneItem[1]
IndexError: string index out of range
2022-01-23 18:48:06,125  ERROR pymapmanager.logger  logger.py handle_exception() line:88 -- Uncaught exception
Traceback (most recent call last):
  File "pymapmanager/pointAnnotations.py", line 71, in <module>
    la = pointAnnotations(stackBasePath)
  File "pymapmanager/pointAnnotations.py", line 15, in __init__
    self.load()
  File "pymapmanager/pointAnnotations.py", line 40, in load
    value = oneItem[1]
IndexError: list index out of range
2022-01-23 18:51:10,132  ERROR pymapmanager.logger  logger.py handle_exception() line:88 -- Uncaught exception
Traceback (most recent call last):
  File "pymapmanager/pointAnnotations.py", line 73, in <module>
    la = pointAnnotations(stackBasePath)
  File "pymapmanager/pointAnnotations.py", line 15, in __init__
    self.load()
  File "pymapmanager/pointAnnotations.py", line 42, in load
    value = oneItem[1]
IndexError: list index out of range
2022-01-23 19:06:05,550  ERROR pymapmanager.logger  logger.py handle_exception() line:88 -- Uncaught exception
Traceback (most recent call last):
  File "pymapmanager/stack.py", line 218, in <module>
    myStack = stack(tifPath)
  File "pymapmanager/stack.py", line 67, in __init__
    self.loadAnnotations()
  File "pymapmanager/stack.py", line 173, in loadAnnotations
    self._annotations = pymapmanager.pointAnnotations.pointAnnotations(self._getBaseName())
AttributeError: module 'pymapmanager' has no attribute 'pointAnnotations'
2022-01-23 19:10:32,114  ERROR pymapmanager.logger  logger.py handle_exception() line:88 -- Uncaught exception
Traceback (most recent call last):
  File "pymapmanager/stack.py", line 231, in <module>
    xyzAnnotation = myStack.getPointAnnotations().getPoints(roitType=['spineROI'])
TypeError: getPoints() got an unexpected keyword argument 'roitType'
2022-01-23 19:37:43,980  ERROR pymapmanager.logger  logger.py handle_exception() line:88 -- Uncaught exception
Traceback (most recent call last):
  File "pymapmanager/pointAnnotations.py", line 91, in <module>
    xyz  = la.getPoints_xyz()
  File "pymapmanager/pointAnnotations.py", line 82, in getPoints_xyz
    df = df[df['roiType'].isin(roiType)]
  File "/home/cudmore/Sites/PyMapManager/mm_env/lib/python3.8/site-packages/pandas/core/series.py", line 5025, in isin
    result = algorithms.isin(self._values, values)
  File "/home/cudmore/Sites/PyMapManager/mm_env/lib/python3.8/site-packages/pandas/core/algorithms.py", line 459, in isin
    raise TypeError(
TypeError: only list-like objects are allowed to be passed to isin(), you passed a [str]
2022-01-23 19:44:34,005  ERROR pymapmanager.logger  logger.py handle_exception() line:88 -- Uncaught exception
Traceback (most recent call last):
  File "pymapmanager/pointAnnotations.py", line 111, in <module>
    xyz  = la.getPoints_xyz(asPixel=True)
  File "pymapmanager/pointAnnotations.py", line 102, in getPoints_xyz
    ret[:,0] /= self._voxelx
TypeError: ufunc 'true_divide' not supported for the input types, and the inputs could not be safely coerced to any supported types according to the casting rule ''safe''
2022-01-23 19:45:07,655  ERROR pymapmanager.logger  logger.py handle_exception() line:88 -- Uncaught exception
Traceback (most recent call last):
  File "pymapmanager/pointAnnotations.py", line 111, in <module>
    xyz  = la.getPoints_xyz(asPixel=True)
  File "pymapmanager/pointAnnotations.py", line 102, in getPoints_xyz
    ret[:,0] = ret[:,0] / self._voxelx
TypeError: ufunc 'true_divide' not supported for the input types, and the inputs could not be safely coerced to any supported types according to the casting rule ''safe''
2022-01-23 19:45:39,124  ERROR pymapmanager.logger  logger.py handle_exception() line:88 -- Uncaught exception
Traceback (most recent call last):
  File "pymapmanager/pointAnnotations.py", line 112, in <module>
    xyz  = la.getPoints_xyz(asPixel=True)
  File "pymapmanager/pointAnnotations.py", line 103, in getPoints_xyz
    ret[:,0] /=self._voxelx
TypeError: ufunc 'true_divide' not supported for the input types, and the inputs could not be safely coerced to any supported types according to the casting rule ''safe''
2022-01-23 19:45:54,272  ERROR pymapmanager.logger  logger.py handle_exception() line:88 -- Uncaught exception
Traceback (most recent call last):
  File "pymapmanager/pointAnnotations.py", line 112, in <module>
    xyz  = la.getPoints_xyz(asPixel=True)
  File "pymapmanager/pointAnnotations.py", line 103, in getPoints_xyz
    ret[:,0] /=self._voxelx
TypeError: ufunc 'true_divide' not supported for the input types, and the inputs could not be safely coerced to any supported types according to the casting rule ''safe''
2022-01-23 19:47:40,410  ERROR pymapmanager.logger  logger.py handle_exception() line:88 -- Uncaught exception
Traceback (most recent call last):
  File "pymapmanager/stack.py", line 249, in <module>
    run()
  File "pymapmanager/stack.py", line 219, in run
    myStack = stack(tifPath)
  File "pymapmanager/stack.py", line 69, in __init__
    self.loadLines()
  File "pymapmanager/stack.py", line 177, in loadLines
    self._lines = pymapmanager.lineAnnotations.lineAnnotations(self._getBaseName())
  File "/home/cudmore/Sites/PyMapManager/pymapmanager/lineAnnotations.py", line 20, in __init__
    self.load()
  File "/home/cudmore/Sites/PyMapManager/pymapmanager/lineAnnotations.py", line 43, in load
    d = dict(s.split('=') for s in header)
ValueError: dictionary update sequence element #0 has length 6; 2 is required
2022-01-23 19:49:11,311  ERROR pymapmanager.logger  logger.py handle_exception() line:88 -- Uncaught exception
Traceback (most recent call last):
  File "pymapmanager/stack.py", line 249, in <module>
    run()
  File "pymapmanager/stack.py", line 219, in run
    myStack = stack(tifPath)
  File "pymapmanager/stack.py", line 69, in __init__
    self.loadLines()
  File "pymapmanager/stack.py", line 177, in loadLines
    self._lines = pymapmanager.lineAnnotations.lineAnnotations(self._getBaseName())
  File "/home/cudmore/Sites/PyMapManager/pymapmanager/lineAnnotations.py", line 20, in __init__
    self.load()
  File "/home/cudmore/Sites/PyMapManager/pymapmanager/lineAnnotations.py", line 44, in load
    d = dict(s.split('=') for s in header)
ValueError: dictionary update sequence element #0 has length 6; 2 is required
2022-01-23 19:49:24,743  ERROR pymapmanager.logger  logger.py handle_exception() line:88 -- Uncaught exception
Traceback (most recent call last):
  File "pymapmanager/stack.py", line 249, in <module>
    run()
  File "pymapmanager/stack.py", line 219, in run
    myStack = stack(tifPath)
  File "pymapmanager/stack.py", line 69, in __init__
    self.loadLines()
  File "pymapmanager/stack.py", line 177, in loadLines
    self._lines = pymapmanager.lineAnnotations.lineAnnotations(self._getBaseName())
  File "/home/cudmore/Sites/PyMapManager/pymapmanager/lineAnnotations.py", line 20, in __init__
    self.load()
  File "/home/cudmore/Sites/PyMapManager/pymapmanager/lineAnnotations.py", line 44, in load
    d = dict(s.split('=') for s in header)
ValueError: dictionary update sequence element #0 has length 6; 2 is required
2022-01-23 20:02:30,476  ERROR pymapmanager.logger  logger.py handle_exception() line:88 -- Uncaught exception
Traceback (most recent call last):
  File "pymapmanager/stack.py", line 252, in <module>
    run()
  File "pymapmanager/stack.py", line 245, in run
    pymapmanager.plotting.plotMax()
AttributeError: module 'pymapmanager' has no attribute 'plotting'
2022-01-23 20:22:29,792  ERROR pymapmanager.logger  logger.py handle_exception() line:88 -- Uncaught exception
Traceback (most recent call last):
  File "pymapmanager/plotting/plottingUtils.py", line 36, in <module>
    run()
  File "pymapmanager/plotting/plottingUtils.py", line 28, in run
    myStack = pymapmanager.stack.stack(tifPath)
  File "/home/cudmore/Sites/PyMapManager/pymapmanager/stack.py", line 69, in __init__
    self.loadLines()
  File "/home/cudmore/Sites/PyMapManager/pymapmanager/stack.py", line 177, in loadLines
    self._lines = pymapmanager.lineAnnotations.lineAnnotations(self._getBaseName())
  File "/home/cudmore/Sites/PyMapManager/pymapmanager/lineAnnotations.py", line 23, in __init__
    self.load()
  File "/home/cudmore/Sites/PyMapManager/pymapmanager/lineAnnotations.py", line 50, in load
    self._voxelx = float(value)
NameError: name 'value' is not defined
2022-01-23 20:23:08,972  ERROR pymapmanager.logger  logger.py handle_exception() line:88 -- Uncaught exception
Traceback (most recent call last):
  File "pymapmanager/plotting/plottingUtils.py", line 36, in <module>
    run()
  File "pymapmanager/plotting/plottingUtils.py", line 28, in run
    myStack = pymapmanager.stack.stack(tifPath)
  File "/home/cudmore/Sites/PyMapManager/pymapmanager/stack.py", line 69, in __init__
    self.loadLines()
  File "/home/cudmore/Sites/PyMapManager/pymapmanager/stack.py", line 177, in loadLines
    self._lines = pymapmanager.lineAnnotations.lineAnnotations(self._getBaseName())
  File "/home/cudmore/Sites/PyMapManager/pymapmanager/lineAnnotations.py", line 23, in __init__
    self.load()
  File "/home/cudmore/Sites/PyMapManager/pymapmanager/lineAnnotations.py", line 50, in load
    self._voxelx = float(value)
NameError: name 'value' is not defined
2022-01-23 20:55:43,957  ERROR pymapmanager.logger  logger.py handle_exception() line:88 -- Uncaught exception
Traceback (most recent call last):
  File "pymapmanager/plotting/plottingUtils.py", line 37, in <module>
    run()
  File "pymapmanager/plotting/plottingUtils.py", line 33, in run
    plotMax(myStack, channel=thisChannel)
  File "pymapmanager/plotting/plottingUtils.py", line 15, in plotMax
    numSegments = stack.getLineAnnotations().numSegments
  File "/home/cudmore/Sites/PyMapManager/pymapmanager/lineAnnotations.py", line 61, in numSegments
    parentList = self._dfLine.unique('parentID')
  File "/home/cudmore/Sites/PyMapManager/mm_env/lib/python3.8/site-packages/pandas/core/generic.py", line 5487, in __getattr__
    return object.__getattribute__(self, name)
AttributeError: 'DataFrame' object has no attribute 'unique'
2022-01-24 09:10:55,263  ERROR pymapmanager.logger  logger.py handle_exception() line:88 -- Uncaught exception
Traceback (most recent call last):
  File "pymapmanager/stack.py", line 310, in <module>
    run()
  File "pymapmanager/stack.py", line 277, in run
    myStack = stack(tifPath)
  File "pymapmanager/stack.py", line 66, in __init__
    headerDict = self.loadHeader()
  File "pymapmanager/stack.py", line 122, in loadHeader
    headerPath = self._getHeaderPath()
  File "pymapmanager/stack.py", line 111, in _getHeaderPath
    folderPath = self._getFolderPath()
  File "pymapmanager/stack.py", line 270, in _getFolderPath
    tifFolder, tifFile = os.path.split(self.tifPath)
AttributeError: 'stack' object has no attribute 'tifPath'
2022-01-24 09:11:52,749  WARNING __main__  stack.py loadHeader() line:128 -- Did not find header file /media/cudmore/data/richard/rr30a/stacks/rr30a_s0.json
2022-01-24 09:11:52,756  ERROR pymapmanager.logger  logger.py handle_exception() line:88 -- Uncaught exception
Traceback (most recent call last):
  File "pymapmanager/stack.py", line 310, in <module>
    run()
  File "pymapmanager/stack.py", line 278, in run
    print(myStack)
  File "pymapmanager/stack.py", line 87, in __str__
    printList.append(f'channels: {self.numChannels}')
  File "pymapmanager/stack.py", line 188, in numChannels
    return self._numChannels
AttributeError: 'stack' object has no attribute '_numChannels'
2022-01-24 09:12:21,912  WARNING __main__  stack.py loadHeader() line:130 -- Did not find header file /media/cudmore/data/richard/rr30a/stacks/rr30a_s0.json
2022-01-24 09:12:22,238  ERROR pymapmanager.logger  logger.py handle_exception() line:88 -- Uncaught exception
Traceback (most recent call last):
  File "pymapmanager/stack.py", line 312, in <module>
    run()
  File "pymapmanager/stack.py", line 305, in run
    pymapmanager.plotting.plotMax()
AttributeError: module 'pymapmanager' has no attribute 'plotting'
2022-01-24 09:15:55,178  WARNING __main__  stack.py loadHeader() line:130 -- Did not find header file /media/cudmore/data/richard/rr30a/stacks/rr30a_s0.json
2022-01-24 09:15:55,502  ERROR pymapmanager.logger  logger.py handle_exception() line:88 -- Uncaught exception
Traceback (most recent call last):
  File "pymapmanager/stack.py", line 312, in <module>
    run()
  File "pymapmanager/stack.py", line 305, in run
    pymapmanager.plotting.plotMax()
AttributeError: module 'pymapmanager' has no attribute 'plotting'
2022-01-24 09:16:13,559  WARNING __main__  stack.py loadHeader() line:130 -- Did not find header file /media/cudmore/data/richard/rr30a/stacks/rr30a_s0.json
2022-01-24 09:16:13,879  ERROR pymapmanager.logger  logger.py handle_exception() line:88 -- Uncaught exception
Traceback (most recent call last):
  File "pymapmanager/stack.py", line 312, in <module>
    run()
  File "pymapmanager/stack.py", line 305, in run
    pymapmanager.plotting.plotMax()
AttributeError: module 'pymapmanager' has no attribute 'plotting'
2022-01-24 09:16:38,250  WARNING __main__  stack.py loadHeader() line:130 -- Did not find header file /media/cudmore/data/richard/rr30a/stacks/rr30a_s0.json
2022-01-24 09:16:38,576  ERROR pymapmanager.logger  logger.py handle_exception() line:88 -- Uncaught exception
Traceback (most recent call last):
  File "pymapmanager/stack.py", line 313, in <module>
    run()
  File "pymapmanager/stack.py", line 306, in run
    pymapmanager.plotting.plotMax()
AttributeError: module 'pymapmanager.plotting' has no attribute 'plotMax'
2022-01-24 09:17:12,346  WARNING __main__  stack.py loadHeader() line:130 -- Did not find header file /media/cudmore/data/richard/rr30a/stacks/rr30a_s0.json
2022-01-24 09:17:12,667  ERROR pymapmanager.logger  logger.py handle_exception() line:88 -- Uncaught exception
Traceback (most recent call last):
  File "pymapmanager/stack.py", line 313, in <module>
    run()
  File "pymapmanager/stack.py", line 306, in run
    pymapmanager.plotting.plottingUtils.plotMax()
AttributeError: module 'pymapmanager.plotting' has no attribute 'plottingUtils'
2022-01-24 09:17:33,976  WARNING __main__  stack.py loadHeader() line:130 -- Did not find header file /media/cudmore/data/richard/rr30a/stacks/rr30a_s0.json
2022-01-24 09:17:34,301  ERROR pymapmanager.logger  logger.py handle_exception() line:88 -- Uncaught exception
Traceback (most recent call last):
  File "pymapmanager/stack.py", line 313, in <module>
    run()
  File "pymapmanager/stack.py", line 306, in run
    pymapmanager.plotting.plottingUtils.plotMax()
TypeError: plotMax() missing 1 required positional argument: 'stack'
2022-01-24 09:18:34,992  WARNING __main__  stack.py loadHeader() line:130 -- Did not find header file /media/cudmore/data/richard/rr30a/stacks/rr30a_s0.json
2022-01-24 09:22:05,248  WARNING __main__  stack.py loadHeader() line:131 -- Did not find header file /media/cudmore/data/richard/rr30a/stacks/rr30a_s0.json
2022-01-24 09:22:05,303  ERROR pymapmanager.logger  logger.py handle_exception() line:88 -- Uncaught exception
Traceback (most recent call last):
  File "pymapmanager/stack.py", line 320, in <module>
    run()
  File "pymapmanager/stack.py", line 288, in run
    sys.exit(1)
NameError: name 'sys' is not defined
2022-01-24 09:22:24,031  WARNING __main__  stack.py loadHeader() line:131 -- Did not find header file /media/cudmore/data/richard/rr30a/stacks/rr30a_s0.json
2022-01-24 09:26:14,736  WARNING __main__  stack.py loadHeader() line:136 -- Did not find header file /media/cudmore/data/richard/rr30a/stacks/rr30a_s0.json
2022-01-24 09:26:14,736  ERROR pymapmanager.logger  logger.py handle_exception() line:88 -- Uncaught exception
Traceback (most recent call last):
  File "pymapmanager/stack.py", line 330, in <module>
    run()
  File "pymapmanager/stack.py", line 290, in run
    myStack = stack(tifPath)
  File "pymapmanager/stack.py", line 74, in __init__
    self._header['xPixel'] = imageShape[imageColIdx]
NameError: name 'imageColIdx' is not defined
2022-01-24 09:26:35,418  WARNING __main__  stack.py loadHeader() line:136 -- Did not find header file /media/cudmore/data/richard/rr30a/stacks/rr30a_s0.json
2022-01-24 09:28:37,583  WARNING __main__  stack.py loadHeader() line:140 -- Did not find header file /media/cudmore/data/richard/rr30a/stacks/rr30a_s0.json
2022-01-24 09:28:52,320  WARNING __main__  stack.py loadHeader() line:140 -- Did not find header file /media/cudmore/data/richard/rr30a/stacks/rr30a_s0.json
2022-01-24 09:30:12,298  WARNING __main__  stack.py loadHeader() line:140 -- Did not find header file /media/cudmore/data/richard/rr30a/stacks/rr30a_s0.json
2022-01-24 09:31:21,388  WARNING __main__  stack.py loadHeader() line:141 -- Did not find header file /media/cudmore/data/richard/rr30a/stacks/rr30a_s0.json
2022-01-24 09:31:21,388   INFO __main__  stack.py __init__() line:70 -- Creating header
2022-01-24 09:32:09,352  WARNING __main__  stack.py loadHeader() line:142 -- Did not find header file /media/cudmore/data/richard/rr30a/stacks/rr30a_s0.json
2022-01-24 09:32:09,352   INFO __main__  stack.py __init__() line:70 -- Creating header
2022-01-24 09:32:50,615  WARNING __main__  stack.py loadHeader() line:142 -- Did not find header file /media/cudmore/data/richard/rr30a/stacks/rr30a_s0.json
2022-01-24 09:32:50,615   INFO __main__  stack.py __init__() line:70 -- Creating header
2022-01-24 09:35:24,817  WARNING __main__  stack.py loadHeader() line:143 -- Did not find header file /media/cudmore/data/richard/rr30a/stacks/rr30a_s0.json
2022-01-24 09:35:24,817   INFO __main__  stack.py __init__() line:71 -- Creating header
2022-01-24 09:36:35,600  WARNING __main__  stack.py loadHeader() line:141 -- Did not find header file /media/cudmore/data/richard/rr30a/stacks/rr30a_s0.json
2022-01-24 09:36:35,600   INFO __main__  stack.py __init__() line:71 -- Creating header
2022-01-24 09:37:20,450  WARNING __main__  stack.py loadHeader() line:141 -- Did not find header file /media/cudmore/data/richard/rr30a/stacks/rr30a_s0.json
2022-01-24 09:37:20,450   INFO __main__  stack.py __init__() line:71 -- Creating header
2022-01-24 09:38:09,118  WARNING __main__  stack.py loadHeader() line:142 -- Did not find header file /media/cudmore/data/richard/rr30a/stacks/rr30a_s0.json
2022-01-24 09:38:09,118   INFO __main__  stack.py __init__() line:71 -- Creating header
2022-01-24 09:38:47,601  WARNING __main__  stack.py loadHeader() line:142 -- Did not find header file /media/cudmore/data/richard/rr30a/stacks/rr30a_s0.json
2022-01-24 09:38:47,601   INFO __main__  stack.py __init__() line:71 -- Creating header
2022-01-24 09:38:47,609  ERROR pymapmanager.logger  logger.py handle_exception() line:88 -- Uncaught exception
Traceback (most recent call last):
  File "pymapmanager/stack.py", line 337, in <module>
    run()
  File "pymapmanager/stack.py", line 303, in run
    myStack.saveHeader()
  File "pymapmanager/stack.py", line 133, in saveHeader
    json.dump(self.header, self.header)
  File "/home/cudmore/anaconda3/lib/python3.8/json/__init__.py", line 180, in dump
    fp.write(chunk)
AttributeError: 'dict' object has no attribute 'write'
2022-01-24 09:39:43,817  ERROR pymapmanager.logger  logger.py handle_exception() line:88 -- Uncaught exception
Traceback (most recent call last):
  File "pymapmanager/stack.py", line 337, in <module>
    run()
  File "pymapmanager/stack.py", line 296, in run
    myStack = stack(tifPath)
  File "pymapmanager/stack.py", line 69, in __init__
    headerDict = self.loadHeader()
  File "pymapmanager/stack.py", line 139, in loadHeader
    headerDict = json.load(json_file)
  File "/home/cudmore/anaconda3/lib/python3.8/json/__init__.py", line 293, in load
    return loads(fp.read(),
  File "/home/cudmore/anaconda3/lib/python3.8/json/__init__.py", line 357, in loads
    return _default_decoder.decode(s)
  File "/home/cudmore/anaconda3/lib/python3.8/json/decoder.py", line 337, in decode
    obj, end = self.raw_decode(s, idx=_w(s, 0).end())
  File "/home/cudmore/anaconda3/lib/python3.8/json/decoder.py", line 355, in raw_decode
    raise JSONDecodeError("Expecting value", s, err.value) from None
json.decoder.JSONDecodeError: Expecting value: line 1 column 1 (char 0)
2022-01-24 09:41:24,952  ERROR pymapmanager.logger  logger.py handle_exception() line:88 -- Uncaught exception
Traceback (most recent call last):
  File "pymapmanager/stack.py", line 338, in <module>
    run()
  File "pymapmanager/stack.py", line 297, in run
    myStack = stack(tifPath)
  File "pymapmanager/stack.py", line 69, in __init__
    headerDict = self.loadHeader()
  File "pymapmanager/stack.py", line 140, in loadHeader
    headerDict = json.load(json_file)
  File "/home/cudmore/anaconda3/lib/python3.8/json/__init__.py", line 293, in load
    return loads(fp.read(),
  File "/home/cudmore/anaconda3/lib/python3.8/json/__init__.py", line 357, in loads
    return _default_decoder.decode(s)
  File "/home/cudmore/anaconda3/lib/python3.8/json/decoder.py", line 337, in decode
    obj, end = self.raw_decode(s, idx=_w(s, 0).end())
  File "/home/cudmore/anaconda3/lib/python3.8/json/decoder.py", line 355, in raw_decode
    raise JSONDecodeError("Expecting value", s, err.value) from None
json.decoder.JSONDecodeError: Expecting value: line 1 column 1 (char 0)
2022-01-24 09:42:10,048   INFO __main__  stack.py loadHeader() line:139 -- Loading header /media/cudmore/data/richard/rr30a/stacks/rr30a_s0.json
2022-01-24 09:42:10,048  ERROR pymapmanager.logger  logger.py handle_exception() line:88 -- Uncaught exception
Traceback (most recent call last):
  File "pymapmanager/stack.py", line 339, in <module>
    run()
  File "pymapmanager/stack.py", line 298, in run
    myStack = stack(tifPath)
  File "pymapmanager/stack.py", line 69, in __init__
    headerDict = self.loadHeader()
  File "pymapmanager/stack.py", line 141, in loadHeader
    headerDict = json.load(json_file)
  File "/home/cudmore/anaconda3/lib/python3.8/json/__init__.py", line 293, in load
    return loads(fp.read(),
  File "/home/cudmore/anaconda3/lib/python3.8/json/__init__.py", line 357, in loads
    return _default_decoder.decode(s)
  File "/home/cudmore/anaconda3/lib/python3.8/json/decoder.py", line 337, in decode
    obj, end = self.raw_decode(s, idx=_w(s, 0).end())
  File "/home/cudmore/anaconda3/lib/python3.8/json/decoder.py", line 355, in raw_decode
    raise JSONDecodeError("Expecting value", s, err.value) from None
json.decoder.JSONDecodeError: Expecting value: line 1 column 1 (char 0)
2022-01-24 09:42:55,583  WARNING __main__  stack.py loadHeader() line:144 -- Did not find header file /media/cudmore/data/richard/rr30a/stacks/rr30a_s0.json
2022-01-24 09:42:55,583   INFO __main__  stack.py __init__() line:71 -- Creating header
2022-01-24 09:42:55,590   INFO __main__  stack.py saveHeader() line:134 -- Saved header /media/cudmore/data/richard/rr30a/stacks/rr30a_s0.json
2022-01-24 09:43:47,685   INFO __main__  stack.py loadHeader() line:139 -- Loading header /media/cudmore/data/richard/rr30a/stacks/rr30a_s0.json
2022-01-24 09:43:47,685  ERROR pymapmanager.logger  logger.py handle_exception() line:88 -- Uncaught exception
Traceback (most recent call last):
  File "pymapmanager/stack.py", line 341, in <module>
    run()
  File "pymapmanager/stack.py", line 298, in run
    myStack = stack(tifPath)
  File "pymapmanager/stack.py", line 84, in __init__
    self._header = self.headerDict
AttributeError: 'stack' object has no attribute 'headerDict'
2022-01-24 09:44:24,473   INFO __main__  stack.py loadHeader() line:139 -- Loading header /media/cudmore/data/richard/rr30a/stacks/rr30a_s0.json
2022-01-24 09:44:24,480   INFO __main__  stack.py saveHeader() line:134 -- Saved header /media/cudmore/data/richard/rr30a/stacks/rr30a_s0.json
2022-01-24 09:49:51,965  ERROR pymapmanager.logger  logger.py handle_exception() line:88 -- Uncaught exception
Traceback (most recent call last):
  File "pymapmanager/stack.py", line 346, in <module>
    run()
  File "pymapmanager/stack.py", line 303, in run
    myStack = stack(tifPath)
  File "pymapmanager/stack.py", line 55, in __init__
    self._baseName = self._getBaseName()
  File "pymapmanager/stack.py", line 263, in _getBaseName
    baseName = self._basePath()[1]
AttributeError: 'stack' object has no attribute '_basePath'
2022-01-24 09:51:17,886  ERROR pymapmanager.logger  logger.py handle_exception() line:88 -- Uncaught exception
Traceback (most recent call last):
  File "pymapmanager/stack.py", line 351, in <module>
    run()
  File "pymapmanager/stack.py", line 308, in run
    myStack = stack(tifPath)
  File "pymapmanager/stack.py", line 69, in __init__
    headerDict = self.loadHeader()
  File "pymapmanager/stack.py", line 137, in loadHeader
    headerPath = self._getHeaderPath()
  File "pymapmanager/stack.py", line 125, in _getHeaderPath
    folderPath = self._getEnclosingFolderPath()
  File "pymapmanager/stack.py", line 300, in _getEnclosingFolderPath
    folderPath = os.path.join(tifFolder, self._baseName)
  File "/home/cudmore/anaconda3/lib/python3.8/posixpath.py", line 90, in join
    genericpath._check_arg_types('join', a, *p)
  File "/home/cudmore/anaconda3/lib/python3.8/genericpath.py", line 152, in _check_arg_types
    raise TypeError(f'{funcname}() argument must be str, bytes, or '
TypeError: join() argument must be str, bytes, or os.PathLike object, not 'NoneType'
2022-01-24 09:52:26,727  WARNING __main__  stack.py loadHeader() line:144 -- Did not find header file /media/cudmore/data/richard/rr30a/stacks/m/m.json
2022-01-24 09:52:26,727   INFO __main__  stack.py __init__() line:71 -- Creating header
2022-01-24 09:52:26,734  ERROR pymapmanager.logger  logger.py handle_exception() line:88 -- Uncaught exception
Traceback (most recent call last):
  File "pymapmanager/stack.py", line 352, in <module>
    run()
  File "pymapmanager/stack.py", line 318, in run
    myStack.saveHeader()
  File "pymapmanager/stack.py", line 132, in saveHeader
    with open(headerPath, 'w') as outfile:
FileNotFoundError: [Errno 2] No such file or directory: '/media/cudmore/data/richard/rr30a/stacks/m/m.json'
2022-01-24 09:55:43,980  WARNING __main__  stack.py loadHeader() line:145 -- Did not find header file /media/cudmore/data/richard/rr30a/stacks/m/m.json
2022-01-24 09:55:43,980   INFO __main__  stack.py __init__() line:72 -- Creating header
2022-01-24 09:55:43,988  ERROR pymapmanager.logger  logger.py handle_exception() line:88 -- Uncaught exception
Traceback (most recent call last):
  File "pymapmanager/stack.py", line 354, in <module>
    run()
  File "pymapmanager/stack.py", line 320, in run
    myStack.saveHeader()
  File "pymapmanager/stack.py", line 133, in saveHeader
    with open(headerPath, 'w') as outfile:
FileNotFoundError: [Errno 2] No such file or directory: '/media/cudmore/data/richard/rr30a/stacks/m/m.json'
2022-01-24 09:55:56,084  WARNING __main__  stack.py loadHeader() line:145 -- Did not find header file /media/cudmore/data/richard/rr30a/stacks/m/m.json
2022-01-24 09:55:56,084   INFO __main__  stack.py __init__() line:72 -- Creating header
2022-01-24 09:55:56,092  ERROR pymapmanager.logger  logger.py handle_exception() line:88 -- Uncaught exception
Traceback (most recent call last):
  File "pymapmanager/stack.py", line 354, in <module>
    run()
  File "pymapmanager/stack.py", line 320, in run
    myStack.saveHeader()
  File "pymapmanager/stack.py", line 133, in saveHeader
    with open(headerPath, 'w') as outfile:
FileNotFoundError: [Errno 2] No such file or directory: '/media/cudmore/data/richard/rr30a/stacks/m/m.json'
2022-01-24 09:56:11,321  WARNING __main__  stack.py loadHeader() line:145 -- Did not find header file /media/cudmore/data/richard/rr30a/stacks/rr30a_s0/rr30a_s0.json
2022-01-24 09:56:11,321   INFO __main__  stack.py __init__() line:72 -- Creating header
2022-01-24 09:56:11,328   INFO __main__  stack.py saveHeader() line:135 -- Saved header /media/cudmore/data/richard/rr30a/stacks/rr30a_s0/rr30a_s0.json
2022-01-24 09:56:41,405   INFO __main__  stack.py loadHeader() line:140 -- Loading header /media/cudmore/data/richard/rr30a/stacks/rr30a_s0/rr30a_s0.json
2022-01-24 10:19:26,894   INFO __main__  stack.py loadHeader() line:140 -- Loading header /media/cudmore/data/richard/rr30a/stacks/rr30a_s0/rr30a_s0.json
2022-01-24 10:19:27,026  ERROR pymapmanager.logger  logger.py handle_exception() line:88 -- Uncaught exception
Traceback (most recent call last):
  File "pymapmanager/stack.py", line 352, in <module>
    run()
  File "pymapmanager/stack.py", line 343, in run
    pymapmanager.plotting.plottingUtils.plotMax(myStack)
  File "/home/cudmore/Sites/PyMapManager/pymapmanager/plotting/plottingUtils.py", line 13, in plotMax
    maxProject = stack.getMaxProject(channel=channel)
  File "pymapmanager/stack.py", line 191, in getMaxProject
    return self._images[channelIdx].max(axis=self.imageSliceIdx)
AttributeError: 'NoneType' object has no attribute 'max'
2022-01-24 10:19:57,848   INFO __main__  stack.py loadHeader() line:140 -- Loading header /media/cudmore/data/richard/rr30a/stacks/rr30a_s0/rr30a_s0.json
2022-01-24 10:19:58,085  ERROR pymapmanager.logger  logger.py handle_exception() line:88 -- Uncaught exception
Traceback (most recent call last):
  File "pymapmanager/stack.py", line 352, in <module>
    run()
  File "pymapmanager/stack.py", line 349, in run
    plt.show()
NameError: name 'plt' is not defined
2022-01-24 10:20:12,646   INFO __main__  stack.py loadHeader() line:140 -- Loading header /media/cudmore/data/richard/rr30a/stacks/rr30a_s0/rr30a_s0.json
2022-01-24 10:35:01,095   INFO __main__  stack.py loadHeader() line:140 -- Loading header /media/cudmore/data/richard/rr30a/stacks/rr30a_s0/rr30a_s0.json
2022-01-24 10:36:32,668   INFO __main__  stack.py loadHeader() line:141 -- Loading header /media/cudmore/data/richard/rr30a/stacks/rr30a_s0/rr30a_s0.json
2022-01-24 10:36:32,676  ERROR pymapmanager.logger  logger.py handle_exception() line:88 -- Uncaught exception
Traceback (most recent call last):
  File "pymapmanager/stack.py", line 338, in <module>
    run()
  File "pymapmanager/stack.py", line 305, in run
    myStack.printHeader()
  File "pymapmanager/stack.py", line 106, in printHeader
    print(f'== header for stack {basePath}')
NameError: name 'basePath' is not defined
2022-01-24 10:36:40,752   INFO __main__  stack.py loadHeader() line:141 -- Loading header /media/cudmore/data/richard/rr30a/stacks/rr30a_s0/rr30a_s0.json
2022-01-24 10:36:40,760  ERROR pymapmanager.logger  logger.py handle_exception() line:88 -- Uncaught exception
Traceback (most recent call last):
  File "pymapmanager/stack.py", line 338, in <module>
    run()
  File "pymapmanager/stack.py", line 305, in run
    myStack.printHeader()
  File "pymapmanager/stack.py", line 106, in printHeader
    print(f'== header for stack {_basePath}')
NameError: name '_basePath' is not defined
2022-01-24 10:36:51,977   INFO __main__  stack.py loadHeader() line:141 -- Loading header /media/cudmore/data/richard/rr30a/stacks/rr30a_s0/rr30a_s0.json
2022-01-24 10:42:27,538   INFO __main__  stack.py loadHeader() line:146 -- Loading header /media/cudmore/data/richard/rr30a/stacks/rr30a_s0/rr30a_s0.json
2022-01-24 10:42:27,719  ERROR pymapmanager.logger  logger.py handle_exception() line:88 -- Uncaught exception
Traceback (most recent call last):
  File "pymapmanager/stack.py", line 343, in <module>
    run()
  File "pymapmanager/stack.py", line 334, in run
    pymapmanager.plotting.plottingUtils.plotMax(myStack)
  File "/home/cudmore/Sites/PyMapManager/pymapmanager/plotting/plottingUtils.py", line 16, in plotMax
    right = stack.header['umWidth']
KeyError: 'umWidth'
2022-01-24 10:42:38,008  WARNING __main__  stack.py loadHeader() line:151 -- Did not find header file /media/cudmore/data/richard/rr30a/stacks/rr30a_s0/rr30a_s0.json
2022-01-24 10:42:38,008   INFO __main__  stack.py __init__() line:72 -- Creating header
2022-01-24 10:42:38,008  ERROR pymapmanager.logger  logger.py handle_exception() line:88 -- Uncaught exception
Traceback (most recent call last):
  File "pymapmanager/stack.py", line 343, in <module>
    run()
  File "pymapmanager/stack.py", line 302, in run
    myStack = stack(tifPath)
  File "pymapmanager/stack.py", line 74, in __init__
    self._header['basename'] = self._getBaseName()
AttributeError: 'stack' object has no attribute '_getBaseName'
2022-01-24 10:43:08,435  WARNING __main__  stack.py loadHeader() line:151 -- Did not find header file /media/cudmore/data/richard/rr30a/stacks/rr30a_s0/rr30a_s0.json
2022-01-24 10:43:08,435   INFO __main__  stack.py __init__() line:72 -- Creating header
2022-01-24 10:44:40,841  WARNING __main__  stack.py loadHeader() line:151 -- Did not find header file /media/cudmore/data/richard/rr30a/stacks/rr30a_s0/rr30a_s0.json
2022-01-24 10:44:40,841   INFO __main__  stack.py __init__() line:72 -- Creating header
2022-01-24 10:45:01,953  WARNING __main__  stack.py loadHeader() line:151 -- Did not find header file /media/cudmore/data/richard/rr30a/stacks/rr30a_s0/rr30a_s0.json
2022-01-24 10:45:01,953   INFO __main__  stack.py __init__() line:72 -- Creating header
2022-01-24 10:45:39,858  WARNING __main__  stack.py loadHeader() line:151 -- Did not find header file /media/cudmore/data/richard/rr30a/stacks/rr30a_s0/rr30a_s0.json
2022-01-24 10:45:39,858   INFO __main__  stack.py __init__() line:72 -- Creating header
2022-01-24 10:45:39,990  ERROR pymapmanager.logger  logger.py handle_exception() line:88 -- Uncaught exception
Traceback (most recent call last):
  File "pymapmanager/stack.py", line 343, in <module>
    run()
  File "pymapmanager/stack.py", line 334, in run
    pymapmanager.plotting.plottingUtils.plotMax(myStack, roiType='controlPnt', segmentID=[1])
TypeError: plotMax() got an unexpected keyword argument 'roiType'
2022-01-24 10:47:23,650  WARNING __main__  stack.py loadHeader() line:151 -- Did not find header file /media/cudmore/data/richard/rr30a/stacks/rr30a_s0/rr30a_s0.json
2022-01-24 10:47:23,651   INFO __main__  stack.py __init__() line:72 -- Creating header
2022-01-24 10:47:23,880  ERROR pymapmanager.logger  logger.py handle_exception() line:88 -- Uncaught exception
Traceback (most recent call last):
  File "pymapmanager/stack.py", line 343, in <module>
    run()
  File "pymapmanager/stack.py", line 334, in run
    pymapmanager.plotting.plottingUtils.plotMax(myStack, roiType='controlPnt', segmentID=[1])
  File "/home/cudmore/Sites/PyMapManager/pymapmanager/plotting/plottingUtils.py", line 34, in plotMax
    xyzAnnotation = stack.getPointAnnotations().getPoints_xyz(roiType=roiType, segmentID=segmentID, asPixel=False)
  File "/home/cudmore/Sites/PyMapManager/pymapmanager/pointAnnotations.py", line 102, in getPoints_xyz
    df = df[df['roiType'].isin(roiType)]
  File "/home/cudmore/Sites/PyMapManager/mm_env/lib/python3.8/site-packages/pandas/core/series.py", line 5025, in isin
    result = algorithms.isin(self._values, values)
  File "/home/cudmore/Sites/PyMapManager/mm_env/lib/python3.8/site-packages/pandas/core/algorithms.py", line 459, in isin
    raise TypeError(
TypeError: only list-like objects are allowed to be passed to isin(), you passed a [str]
2022-01-24 10:49:43,445  WARNING __main__  stack.py loadHeader() line:151 -- Did not find header file /media/cudmore/data/richard/rr30a/stacks/rr30a_s0/rr30a_s0.json
2022-01-24 10:49:43,446   INFO __main__  stack.py __init__() line:72 -- Creating header
2022-01-24 10:50:28,354  WARNING __main__  stack.py loadHeader() line:151 -- Did not find header file /media/cudmore/data/richard/rr30a/stacks/rr30a_s0/rr30a_s0.json
2022-01-24 10:50:28,354   INFO __main__  stack.py __init__() line:72 -- Creating header
2022-01-24 10:51:25,969  WARNING __main__  stack.py loadHeader() line:151 -- Did not find header file /media/cudmore/data/richard/rr30a/stacks/rr30a_s0/rr30a_s0.json
2022-01-24 10:51:25,969   INFO __main__  stack.py __init__() line:72 -- Creating header
2022-01-24 10:51:39,192  WARNING __main__  stack.py loadHeader() line:151 -- Did not find header file /media/cudmore/data/richard/rr30a/stacks/rr30a_s0/rr30a_s0.json
2022-01-24 10:51:39,193   INFO __main__  stack.py __init__() line:72 -- Creating header
2022-01-24 10:51:39,200   INFO __main__  stack.py saveHeader() line:141 -- Saved header /media/cudmore/data/richard/rr30a/stacks/rr30a_s0/rr30a_s0.json
2022-01-24 11:02:27,508   INFO __main__  stack.py loadHeader() line:146 -- Loading header /media/cudmore/data/richard/rr30a/stacks/rr30a_s0/rr30a_s0.json
2022-01-24 11:02:27,515   INFO __main__  stack.py saveHeader() line:141 -- Saved header /media/cudmore/data/richard/rr30a/stacks/rr30a_s0/rr30a_s0.json
2022-01-24 11:02:27,744  ERROR pymapmanager.logger  logger.py handle_exception() line:88 -- Uncaught exception
Traceback (most recent call last):
  File "pymapmanager/stack.py", line 346, in <module>
    run()
  File "pymapmanager/stack.py", line 334, in run
    import pymapmanager.plotting.plottingUtils
  File "/home/cudmore/Sites/PyMapManager/pymapmanager/plotting/plottingUtils.py", line 7, in <module>
    def plotMax(stack: pymapmanager.stack.stack,
NameError: name 'pymapmanager' is not defined
2022-01-24 11:07:25,369  ERROR pymapmanager.logger  logger.py handle_exception() line:88 -- Uncaught exception
Traceback (most recent call last):
  File "pymapmanager/stack.py", line 9, in <module>
    import pymapmanager.pointAnnotations
  File "/home/cudmore/Sites/PyMapManager/pymapmanager/pointAnnotations.py", line 9, in <module>
    class pointAnnotations():
  File "/home/cudmore/Sites/PyMapManager/pymapmanager/pointAnnotations.py", line 85, in pointAnnotations
    asPixel : bool = False) -> np.ndarray:
NameError: name 'np' is not defined
2022-01-24 11:07:40,787  ERROR pymapmanager.logger  logger.py handle_exception() line:88 -- Uncaught exception
Traceback (most recent call last):
  File "pymapmanager/stack.py", line 9, in <module>
    import pymapmanager.pointAnnotations
  File "/home/cudmore/Sites/PyMapManager/pymapmanager/pointAnnotations.py", line 9, in <module>
    class pointAnnotations():
  File "/home/cudmore/Sites/PyMapManager/pymapmanager/pointAnnotations.py", line 85, in pointAnnotations
    asPixel : bool = False) -> numpy.ndarray:
NameError: name 'numpy' is not defined
2022-01-24 11:08:10,178   INFO __main__  stack.py loadHeader() line:146 -- Loading header /media/cudmore/data/richard/rr30a/stacks/rr30a_s0/rr30a_s0.json
2022-01-24 11:08:10,186   INFO __main__  stack.py saveHeader() line:141 -- Saved header /media/cudmore/data/richard/rr30a/stacks/rr30a_s0/rr30a_s0.json
2022-01-24 11:30:39,936  ERROR pymapmanager.logger  logger.py handle_exception() line:88 -- Uncaught exception
Traceback (most recent call last):
  File "pymapmanager/map.py", line 67, in <module>
    run()
  File "pymapmanager/map.py", line 64, in run
    myMap = map(folderPath)
  File "pymapmanager/map.py", line 31, in __init__
    loadedDict = self.load()
  File "pymapmanager/map.py", line 44, in load
    if os.path.isfile(mapFilePath):
NameError: name 'mapFilePath' is not defined
2022-01-24 11:31:18,350   INFO __main__  map.py newMap() line:39 -- Making new map: /media/cudmore/data/richard/rr30a/firstMap/firstMap.txt
2022-01-24 11:33:56,672   INFO __main__  map.py newMap() line:46 -- Making new map: /media/cudmore/data/richard/rr30a/firstMap/firstMap.txt
2022-01-24 11:34:11,013   INFO __main__  map.py newMap() line:46 -- Making new map: /media/cudmore/data/richard/rr30a/firstMap/firstMap.txt
2022-01-24 11:39:12,892   INFO __main__  map.py newMap() line:48 -- Making new map: /media/cudmore/data/richard/rr30a/firstMap/firstMap.txt
2022-01-24 11:39:12,941   INFO pymapmanager.stack  stack.py loadHeader() line:146 -- Loading header /media/cudmore/data/richard/rr30a/stacks/rr30a_s0/rr30a_s0.json
2022-01-24 11:42:43,240   INFO __main__  map.py newMap() line:48 -- Making new map: /media/cudmore/data/richard/rr30a/firstMap/firstMap.txt
2022-01-24 11:42:43,290   INFO pymapmanager.stack  stack.py loadHeader() line:148 -- Loading header /media/cudmore/data/richard/rr30a/stacks/rr30a_s0/rr30a_s0.json
2022-01-24 11:42:43,297  ERROR pymapmanager.logger  logger.py handle_exception() line:88 -- Uncaught exception
Traceback (most recent call last):
  File "pymapmanager/map.py", line 98, in <module>
    run()
  File "pymapmanager/map.py", line 95, in run
    myMap.addStack(stackPath)
  File "pymapmanager/map.py", line 75, in addStack
    print(theStack)
  File "/home/cudmore/Sites/PyMapManager/pymapmanager/stack.py", line 105, in __str__
    printList.append(f'annotations: {self.getPointAnnotations().numAnnotation}')
AttributeError: 'pointAnnotations' object has no attribute 'numAnnotation'
2022-01-24 11:42:51,895   INFO __main__  map.py newMap() line:48 -- Making new map: /media/cudmore/data/richard/rr30a/firstMap/firstMap.txt
2022-01-24 11:42:51,944   INFO pymapmanager.stack  stack.py loadHeader() line:148 -- Loading header /media/cudmore/data/richard/rr30a/stacks/rr30a_s0/rr30a_s0.json
2022-01-24 11:42:51,952  ERROR pymapmanager.logger  logger.py handle_exception() line:88 -- Uncaught exception
Traceback (most recent call last):
  File "pymapmanager/map.py", line 98, in <module>
    run()
  File "pymapmanager/map.py", line 95, in run
    myMap.addStack(stackPath)
  File "pymapmanager/map.py", line 75, in addStack
    print(theStack)
  File "/home/cudmore/Sites/PyMapManager/pymapmanager/stack.py", line 105, in __str__
    printList.append(f'annotations: {self.getPointAnnotations().numAnnotations}')
AttributeError: 'pointAnnotations' object has no attribute 'numAnnotations'
2022-01-24 11:43:02,294   INFO __main__  map.py newMap() line:48 -- Making new map: /media/cudmore/data/richard/rr30a/firstMap/firstMap.txt
2022-01-24 11:43:02,344   INFO pymapmanager.stack  stack.py loadHeader() line:148 -- Loading header /media/cudmore/data/richard/rr30a/stacks/rr30a_s0/rr30a_s0.json
2022-01-24 11:45:53,619   INFO __main__  map.py newMap() line:48 -- Making new map: /media/cudmore/data/richard/rr30a/firstMap/firstMap.txt
2022-01-24 11:45:53,668   INFO pymapmanager.stack  stack.py loadHeader() line:148 -- Loading header /media/cudmore/data/richard/rr30a/stacks/rr30a_s0/rr30a_s0.json
2022-01-24 11:46:16,239   INFO __main__  map.py newMap() line:48 -- Making new map: /media/cudmore/data/richard/rr30a/firstMap/firstMap.txt
2022-01-24 11:46:16,287   INFO pymapmanager.stack  stack.py loadHeader() line:148 -- Loading header /media/cudmore/data/richard/rr30a/stacks/rr30a_s0/rr30a_s0.json
2022-01-24 12:40:21,851   INFO __main__  map.py newMap() line:48 -- Making new map: /media/cudmore/data/richard/rr30a/firstMap/firstMap.txt
2022-01-24 12:40:21,851  ERROR pymapmanager.logger  logger.py handle_exception() line:88 -- Uncaught exception
Traceback (most recent call last):
  File "pymapmanager/map.py", line 111, in <module>
    run()
  File "pymapmanager/map.py", line 99, in run
    myMap.addStack(stackPath)
  File "pymapmanager/map.py", line 74, in addStack
    theStack = pymapmanager.stack.stack(stackPath)
  File "/home/cudmore/Sites/PyMapManager/pymapmanager/stack.py", line 58, in __init__
    self._numChannels = self._inferNumberOfChannels()  # TODO (cudmore) we need to infer this from tif file _ch (need to look on harddrive)
  File "/home/cudmore/Sites/PyMapManager/pymapmanager/stack.py", line 278, in _inferNumberOfChannels
    if os.path.isfile(potentialTifPath):
NameError: name 'potentialTifPath' is not defined
2022-01-24 12:40:36,706   INFO __main__  map.py newMap() line:48 -- Making new map: /media/cudmore/data/richard/rr30a/firstMap/firstMap.txt
2022-01-24 12:40:36,757   INFO pymapmanager.stack  stack.py loadHeader() line:148 -- Loading header /media/cudmore/data/richard/rr30a/stacks/rr30a_s0/rr30a_s0.json
2022-01-24 12:45:03,534   INFO __main__  map.py newMap() line:48 -- Making new map: /media/cudmore/data/richard/rr30a/firstMap/firstMap.txt
2022-01-24 12:45:03,588   INFO pymapmanager.stack  stack.py loadHeader() line:158 -- Loading header /media/cudmore/data/richard/rr30a/stacks/rr30a_s0/rr30a_s0.json
2022-01-24 12:51:14,992  ERROR pymapmanager.stack  stack.py __init__() line:56 -- Did not find tifPath: /media/cudmore/data/richard/rr30a/firstMap
2022-01-24 12:51:14,992  ERROR pymapmanager.logger  logger.py handle_exception() line:88 -- Uncaught exception
Traceback (most recent call last):
  File "pymapmanager/map.py", line 120, in <module>
    run()
  File "pymapmanager/map.py", line 104, in run
    myMap = map(folderPath)
  File "pymapmanager/map.py", line 78, in __init__
    print(theStack)
  File "/home/cudmore/Sites/PyMapManager/pymapmanager/stack.py", line 110, in __str__
    printList.append(f'base name: {self._baseName}')
AttributeError: 'stack' object has no attribute '_baseName'
2022-01-24 12:53:50,849   INFO __main__  map.py newMap() line:49 -- Making new map: /media/cudmore/data/richard/rr30a/firstMap/firstMap.txt
2022-01-24 12:53:50,850  ERROR pymapmanager.logger  logger.py handle_exception() line:88 -- Uncaught exception
Traceback (most recent call last):
  File "pymapmanager/map.py", line 120, in <module>
    run()
  File "pymapmanager/map.py", line 108, in run
    myMap.addStack(stackPath)
  File "pymapmanager/map.py", line 77, in addStack
    theStack = pymapmanager.stack.stack(tifPath, loadData=False)
NameError: name 'tifPath' is not defined
2022-01-24 12:54:04,053   INFO __main__  map.py newMap() line:49 -- Making new map: /media/cudmore/data/richard/rr30a/firstMap/firstMap.txt
2022-01-24 12:54:04,105   INFO pymapmanager.stack  stack.py loadHeader() line:158 -- Loading header /media/cudmore/data/richard/rr30a/stacks/rr30a_s0/rr30a_s0.json
2022-01-24 12:54:40,361   INFO __main__  map.py newMap() line:49 -- Making new map: /media/cudmore/data/richard/rr30a/firstMap/firstMap.txt
2022-01-24 12:54:40,361   INFO pymapmanager.stack  stack.py loadHeader() line:158 -- Loading header /media/cudmore/data/richard/rr30a/stacks/rr30a_s0/rr30a_s0.json
2022-01-24 12:54:40,491  ERROR pymapmanager.logger  logger.py handle_exception() line:88 -- Uncaught exception
Traceback (most recent call last):
  File "pymapmanager/map.py", line 120, in <module>
    run()
  File "pymapmanager/map.py", line 116, in run
    pymapmanager.plotting.plottingUtils.plotMax(myStack, roiType=roiType, segmentID=segmentID)
  File "/home/cudmore/Sites/PyMapManager/pymapmanager/plotting/plottingUtils.py", line 25, in plotMax
    maxProject = stack.getMaxProject(channel=channel)
  File "/home/cudmore/Sites/PyMapManager/pymapmanager/stack.py", line 210, in getMaxProject
    return self._images[channelIdx].max(axis=self.imageSliceIdx)
AttributeError: 'NoneType' object has no attribute 'max'
2022-01-24 12:55:10,697   INFO __main__  map.py newMap() line:49 -- Making new map: /media/cudmore/data/richard/rr30a/firstMap/firstMap.txt
2022-01-24 12:55:10,698   INFO pymapmanager.stack  stack.py loadHeader() line:158 -- Loading header /media/cudmore/data/richard/rr30a/stacks/rr30a_s0/rr30a_s0.json
2022-01-24 12:56:02,989   INFO __main__  map.py newMap() line:49 -- Making new map: /media/cudmore/data/richard/rr30a/firstMap/firstMap.txt
2022-01-24 12:56:02,989   INFO pymapmanager.stack  stack.py loadHeader() line:158 -- Loading header /media/cudmore/data/richard/rr30a/stacks/rr30a_s0/rr30a_s0.json
2022-01-24 12:57:42,836   INFO __main__  map.py newMap() line:49 -- Making new map: /media/cudmore/data/richard/rr30a/firstMap/firstMap.txt
2022-01-24 12:57:42,836   INFO pymapmanager.stack  stack.py loadHeader() line:158 -- Loading header /media/cudmore/data/richard/rr30a/stacks/rr30a_s0/rr30a_s0.json
2022-01-24 13:03:18,136   INFO __main__  map.py newMap() line:49 -- Making new map: /media/cudmore/data/richard/rr30a/firstMap/firstMap.txt
2022-01-24 13:03:18,136   INFO pymapmanager.stack  stack.py loadHeader() line:158 -- Loading header /media/cudmore/data/richard/rr30a/stacks/rr30a_s0/rr30a_s0.json
2022-01-24 13:05:22,250   INFO __main__  map.py newMap() line:49 -- Making new map: /media/cudmore/data/richard/rr30a/firstMap/firstMap.txt
2022-01-24 13:05:22,250  WARNING pymapmanager.stack  stack.py loadHeader() line:163 -- Did not find header file /media/cudmore/data/richard/rr30a/naked-tif/rr30a_s0/rr30a_s0.json
2022-01-24 13:05:22,250   INFO pymapmanager.stack  stack.py __init__() line:82 -- Creating header
2022-01-24 13:05:22,250  ERROR pymapmanager.pointAnnotations  pointAnnotations.py load() line:61 -- Did not find annotation file: /media/cudmore/data/richard/rr30a/naked-tif/rr30a_s0/rr30a_s0_db2.txt
2022-01-24 13:05:22,250  ERROR pymapmanager.logger  logger.py handle_exception() line:88 -- Uncaught exception
Traceback (most recent call last):
  File "pymapmanager/map.py", line 125, in <module>
    run()
  File "pymapmanager/map.py", line 111, in run
    myMap.addStack(stackPath)
  File "pymapmanager/map.py", line 77, in addStack
    theStack = pymapmanager.stack.stack(tifPath, loadData=False)
  File "/home/cudmore/Sites/PyMapManager/pymapmanager/stack.py", line 100, in __init__
    self.loadAnnotations()
  File "/home/cudmore/Sites/PyMapManager/pymapmanager/stack.py", line 246, in loadAnnotations
    self._annotations = pymapmanager.pointAnnotations.pointAnnotations(self._basePath)
  File "/home/cudmore/Sites/PyMapManager/pymapmanager/pointAnnotations.py", line 29, in __init__
    self.load()
  File "/home/cudmore/Sites/PyMapManager/pymapmanager/pointAnnotations.py", line 62, in load
    raise OSError(errno.ENOENT, os.strerror(errno.ENOENT), annotationPath)
FileNotFoundError: [Errno 2] No such file or directory: '/media/cudmore/data/richard/rr30a/naked-tif/rr30a_s0/rr30a_s0_db2.txt'
2022-01-24 13:07:05,708   INFO __main__  map.py newMap() line:49 -- Making new map: /media/cudmore/data/richard/rr30a/firstMap/firstMap.txt
2022-01-24 13:07:05,708  WARNING pymapmanager.stack  stack.py loadHeader() line:164 -- Did not find header file /media/cudmore/data/richard/rr30a/naked-tif/rr30a_s0/rr30a_s0.json
2022-01-24 13:07:05,708   INFO pymapmanager.stack  stack.py __init__() line:83 -- Creating header
2022-01-24 13:07:05,708  ERROR pymapmanager.pointAnnotations  pointAnnotations.py load() line:61 -- Did not find annotation file: /media/cudmore/data/richard/rr30a/naked-tif/rr30a_s0/rr30a_s0_db2.txt
2022-01-24 13:07:05,708  ERROR pymapmanager.lineAnnotations  lineAnnotations.py load() line:38 -- Did not find line file /media/cudmore/data/richard/rr30a/naked-tif/rr30a_s0/rr30a_s0_l.txt
2022-01-24 13:07:05,708  ERROR pymapmanager.logger  logger.py handle_exception() line:88 -- Uncaught exception
Traceback (most recent call last):
  File "pymapmanager/map.py", line 125, in <module>
    run()
  File "pymapmanager/map.py", line 111, in run
    myMap.addStack(stackPath)
  File "pymapmanager/map.py", line 77, in addStack
    theStack = pymapmanager.stack.stack(tifPath, loadData=False)
  File "/home/cudmore/Sites/PyMapManager/pymapmanager/stack.py", line 102, in __init__
    self.loadLines()
  File "/home/cudmore/Sites/PyMapManager/pymapmanager/stack.py", line 254, in loadLines
    self._lines = pymapmanager.lineAnnotations.lineAnnotations(self._basePath)
  File "/home/cudmore/Sites/PyMapManager/pymapmanager/lineAnnotations.py", line 24, in __init__
    self.load()
  File "/home/cudmore/Sites/PyMapManager/pymapmanager/lineAnnotations.py", line 39, in load
    raise OSError(errno.ENOENT, os.strerror(errno.ENOENT), annotationPath)
NameError: name 'annotationPath' is not defined
2022-01-24 13:07:20,211   INFO __main__  map.py newMap() line:49 -- Making new map: /media/cudmore/data/richard/rr30a/firstMap/firstMap.txt
2022-01-24 13:07:20,211  WARNING pymapmanager.stack  stack.py loadHeader() line:164 -- Did not find header file /media/cudmore/data/richard/rr30a/naked-tif/rr30a_s0/rr30a_s0.json
2022-01-24 13:07:20,211   INFO pymapmanager.stack  stack.py __init__() line:83 -- Creating header
2022-01-24 13:07:20,211  ERROR pymapmanager.pointAnnotations  pointAnnotations.py load() line:61 -- Did not find annotation file: /media/cudmore/data/richard/rr30a/naked-tif/rr30a_s0/rr30a_s0_db2.txt
2022-01-24 13:07:20,211  ERROR pymapmanager.lineAnnotations  lineAnnotations.py load() line:38 -- Did not find line file /media/cudmore/data/richard/rr30a/naked-tif/rr30a_s0/rr30a_s0_l.txt
2022-01-24 13:07:20,211  ERROR pymapmanager.logger  logger.py handle_exception() line:88 -- Uncaught exception
Traceback (most recent call last):
  File "pymapmanager/map.py", line 125, in <module>
    run()
  File "pymapmanager/map.py", line 111, in run
    myMap.addStack(stackPath)
  File "pymapmanager/map.py", line 78, in addStack
    print(theStack)
  File "/home/cudmore/Sites/PyMapManager/pymapmanager/stack.py", line 116, in __str__
    printList.append(f'annotations: {self.getPointAnnotations().numAnnotations}')
AttributeError: 'NoneType' object has no attribute 'numAnnotations'
2022-01-24 13:16:15,824   INFO __main__  map.py newMap() line:49 -- Making new map: /media/cudmore/data/richard/rr30a/firstMap/firstMap.txt
2022-01-24 13:16:15,824  WARNING pymapmanager.stack  stack.py loadHeader() line:164 -- Did not find header file /media/cudmore/data/richard/rr30a/naked-tif/rr30a_s0/rr30a_s0.json
2022-01-24 13:16:15,824   INFO pymapmanager.stack  stack.py __init__() line:83 -- Creating header
2022-01-24 13:16:15,824  ERROR pymapmanager.pointAnnotations  pointAnnotations.py load() line:74 -- Did not find annotation file: /media/cudmore/data/richard/rr30a/naked-tif/rr30a_s0/rr30a_s0_db2.txt
2022-01-24 13:16:15,824  ERROR pymapmanager.logger  logger.py handle_exception() line:88 -- Uncaught exception
Traceback (most recent call last):
  File "/home/cudmore/Sites/PyMapManager/pymapmanager/pointAnnotations.py", line 31, in __init__
    self._dfPoints = self.load()
  File "/home/cudmore/Sites/PyMapManager/pymapmanager/pointAnnotations.py", line 75, in load
    raise OSError(errno.ENOENT, os.strerror(errno.ENOENT), annotationPath)
FileNotFoundError: [Errno 2] No such file or directory: '/media/cudmore/data/richard/rr30a/naked-tif/rr30a_s0/rr30a_s0_db2.txt'

During handling of the above exception, another exception occurred:

Traceback (most recent call last):
  File "pymapmanager/map.py", line 125, in <module>
    run()
  File "pymapmanager/map.py", line 111, in run
    myMap.addStack(stackPath)
  File "pymapmanager/map.py", line 77, in addStack
    theStack = pymapmanager.stack.stack(tifPath, loadData=False)
  File "/home/cudmore/Sites/PyMapManager/pymapmanager/stack.py", line 101, in __init__
    self.loadAnnotations()
  File "/home/cudmore/Sites/PyMapManager/pymapmanager/stack.py", line 248, in loadAnnotations
    self._annotations = pymapmanager.pointAnnotations.pointAnnotations(self._basePath)
  File "/home/cudmore/Sites/PyMapManager/pymapmanager/pointAnnotations.py", line 33, in __init__
    self._dfPoints = _getDefaultDataFrame()
NameError: name '_getDefaultDataFrame' is not defined
2022-01-24 13:16:25,447   INFO __main__  map.py newMap() line:49 -- Making new map: /media/cudmore/data/richard/rr30a/firstMap/firstMap.txt
2022-01-24 13:16:25,447  WARNING pymapmanager.stack  stack.py loadHeader() line:164 -- Did not find header file /media/cudmore/data/richard/rr30a/naked-tif/rr30a_s0/rr30a_s0.json
2022-01-24 13:16:25,447   INFO pymapmanager.stack  stack.py __init__() line:83 -- Creating header
2022-01-24 13:16:25,447  ERROR pymapmanager.pointAnnotations  pointAnnotations.py load() line:74 -- Did not find annotation file: /media/cudmore/data/richard/rr30a/naked-tif/rr30a_s0/rr30a_s0_db2.txt
2022-01-24 13:16:25,449  ERROR pymapmanager.lineAnnotations  lineAnnotations.py load() line:59 -- Did not find line file /media/cudmore/data/richard/rr30a/naked-tif/rr30a_s0/rr30a_s0_l.txt
2022-01-24 13:16:25,449  ERROR pymapmanager.logger  logger.py handle_exception() line:88 -- Uncaught exception
Traceback (most recent call last):
  File "/home/cudmore/Sites/PyMapManager/mm_env/lib/python3.8/site-packages/pandas/core/indexes/base.py", line 3361, in get_loc
    return self._engine.get_loc(casted_key)
  File "pandas/_libs/index.pyx", line 76, in pandas._libs.index.IndexEngine.get_loc
  File "pandas/_libs/index.pyx", line 108, in pandas._libs.index.IndexEngine.get_loc
  File "pandas/_libs/hashtable_class_helper.pxi", line 5198, in pandas._libs.hashtable.PyObjectHashTable.get_item
  File "pandas/_libs/hashtable_class_helper.pxi", line 5206, in pandas._libs.hashtable.PyObjectHashTable.get_item
KeyError: 'parentID'

The above exception was the direct cause of the following exception:

Traceback (most recent call last):
  File "pymapmanager/map.py", line 125, in <module>
    run()
  File "pymapmanager/map.py", line 111, in run
    myMap.addStack(stackPath)
  File "pymapmanager/map.py", line 78, in addStack
    print(theStack)
  File "/home/cudmore/Sites/PyMapManager/pymapmanager/stack.py", line 117, in __str__
    printList.append(f'segments: {self.getLineAnnotations().numSegments}')
  File "/home/cudmore/Sites/PyMapManager/pymapmanager/lineAnnotations.py", line 87, in numSegments
    parentList = self._dfLine['parentID'].unique()
  File "/home/cudmore/Sites/PyMapManager/mm_env/lib/python3.8/site-packages/pandas/core/frame.py", line 3458, in __getitem__
    indexer = self.columns.get_loc(key)
  File "/home/cudmore/Sites/PyMapManager/mm_env/lib/python3.8/site-packages/pandas/core/indexes/base.py", line 3363, in get_loc
    raise KeyError(key) from err
KeyError: 'parentID'
2022-01-24 13:17:14,135   INFO __main__  map.py newMap() line:49 -- Making new map: /media/cudmore/data/richard/rr30a/firstMap/firstMap.txt
2022-01-24 13:17:14,135  WARNING pymapmanager.stack  stack.py loadHeader() line:164 -- Did not find header file /media/cudmore/data/richard/rr30a/naked-tif/rr30a_s0/rr30a_s0.json
2022-01-24 13:17:14,135   INFO pymapmanager.stack  stack.py __init__() line:83 -- Creating header
2022-01-24 13:17:14,135  ERROR pymapmanager.pointAnnotations  pointAnnotations.py load() line:74 -- Did not find annotation file: /media/cudmore/data/richard/rr30a/naked-tif/rr30a_s0/rr30a_s0_db2.txt
2022-01-24 13:17:14,137  ERROR pymapmanager.lineAnnotations  lineAnnotations.py load() line:59 -- Did not find line file /media/cudmore/data/richard/rr30a/naked-tif/rr30a_s0/rr30a_s0_l.txt
2022-01-24 14:15:04,078  ERROR pymapmanager.logger  logger.py handle_exception() line:88 -- Uncaught exception
Traceback (most recent call last):
  File "pymapmanager/pointAnnotations2.py", line 13, in <module>
    class pointAnnotations(pymapmanager.baseAnnotations):
TypeError: module() takes at most 2 arguments (3 given)
2022-01-24 14:15:46,566  ERROR pymapmanager.logger  logger.py handle_exception() line:88 -- Uncaught exception
Traceback (most recent call last):
  File "pymapmanager/pointAnnotations2.py", line 13, in <module>
    class pointAnnotations(baseAnnotations):
TypeError: module() takes at most 2 arguments (3 given)
2022-01-24 14:16:32,274  ERROR pymapmanager.logger  logger.py handle_exception() line:88 -- Uncaught exception
Traceback (most recent call last):
  File "pymapmanager/pointAnnotations2.py", line 13, in <module>
    class pointAnnotations(baseAnnotations.baseAnnotations):
AttributeError: module 'pymapmanager.baseAnnotations' has no attribute 'baseAnnotations'
2022-01-24 14:16:45,274  ERROR pymapmanager.logger  logger.py handle_exception() line:88 -- Uncaught exception
Traceback (most recent call last):
  File "pymapmanager/pointAnnotations2.py", line 13, in <module>
    class pointAnnotations(baseAnnotations):
TypeError: module() takes at most 2 arguments (3 given)
2022-01-24 14:17:20,089  ERROR pymapmanager.logger  logger.py handle_exception() line:88 -- Uncaught exception
Traceback (most recent call last):
  File "pymapmanager/pointAnnotations2.py", line 13, in <module>
    class pointAnnotations(pymapmanager.baseAnnotations.baseAnnotations):
AttributeError: module 'pymapmanager.baseAnnotations' has no attribute 'baseAnnotations'
2022-01-24 14:17:52,325  ERROR pymapmanager.logger  logger.py handle_exception() line:88 -- Uncaught exception
Traceback (most recent call last):
  File "pymapmanager/pointAnnotations2.py", line 13, in <module>
    class pointAnnotations(pymapmanager.baseAnnotations.baseAnnotations):
AttributeError: module 'pymapmanager.baseAnnotations' has no attribute 'baseAnnotations'
2022-01-24 14:18:15,867  ERROR pymapmanager.logger  logger.py handle_exception() line:88 -- Uncaught exception
Traceback (most recent call last):
  File "pymapmanager/pointAnnotations2.py", line 8, in <module>
    import pymapmanager.baseAnnotations
  File "/home/cudmore/Sites/PyMapManager/pymapmanager/baseAnnotations.py", line 11, in <module>
    class baseAnnotations():
  File "/home/cudmore/Sites/PyMapManager/pymapmanager/baseAnnotations.py", line 88, in baseAnnotations
    asPixel : bool = False) -> np.ndarray:
NameError: name 'np' is not defined
2022-01-24 14:18:32,877  ERROR pymapmanager.logger  logger.py handle_exception() line:88 -- Uncaught exception
Traceback (most recent call last):
  File "pymapmanager/pointAnnotations2.py", line 44, in <module>
    run()
  File "pymapmanager/pointAnnotations2.py", line 33, in run
    xyz  = la.getPoints_xyz(asPixel=True)
  File "/home/cudmore/Sites/PyMapManager/pymapmanager/baseAnnotations.py", line 105, in getPoints_xyz
    df = self._dfPoints
AttributeError: 'pointAnnotations' object has no attribute '_dfPoints'
2022-01-24 14:18:54,397  ERROR pymapmanager.logger  logger.py handle_exception() line:88 -- Uncaught exception
Traceback (most recent call last):
  File "pymapmanager/pointAnnotations2.py", line 44, in <module>
    run()
  File "pymapmanager/pointAnnotations2.py", line 34, in run
    print(xyz.shape)  # unlike .tif image data, order is (x, y, slice)
AttributeError: 'NoneType' object has no attribute 'shape'
2022-01-24 14:20:17,011  ERROR pymapmanager.logger  logger.py handle_exception() line:88 -- Uncaught exception
Traceback (most recent call last):
  File "pymapmanager/pointAnnotations2.py", line 13, in <module>
    class pointAnnotations(pymapmanager.baseAnnotations):
TypeError: module() takes at most 2 arguments (3 given)
2022-01-24 14:20:49,604  ERROR pymapmanager.logger  logger.py handle_exception() line:88 -- Uncaught exception
Traceback (most recent call last):
  File "pymapmanager/pointAnnotations2.py", line 45, in <module>
    run()
  File "pymapmanager/pointAnnotations2.py", line 33, in run
    print('numAnnotations:', la.numAnnotations())
  File "/home/cudmore/Sites/PyMapManager/pymapmanager/baseAnnotations.py", line 55, in numAnnotations
    return len(self._df)
TypeError: object of type 'NoneType' has no len()
2022-01-24 14:21:13,291  ERROR pymapmanager.logger  logger.py handle_exception() line:88 -- Uncaught exception
Traceback (most recent call last):
  File "pymapmanager/pointAnnotations2.py", line 43, in <module>
    run()
  File "pymapmanager/pointAnnotations2.py", line 31, in run
    print('numAnnotations:', la.numAnnotations())
  File "/home/cudmore/Sites/PyMapManager/pymapmanager/baseAnnotations.py", line 55, in numAnnotations
    return len(self._df)
TypeError: object of type 'NoneType' has no len()
2022-01-24 14:22:04,349  ERROR pymapmanager.logger  logger.py handle_exception() line:88 -- Uncaught exception
Traceback (most recent call last):
  File "pymapmanager/pointAnnotations2.py", line 45, in <module>
    run()
  File "pymapmanager/pointAnnotations2.py", line 33, in run
    print('numAnnotations:', la.numAnnotations())
  File "/home/cudmore/Sites/PyMapManager/pymapmanager/baseAnnotations.py", line 57, in numAnnotations
    return len(self._df)
TypeError: object of type 'NoneType' has no len()
2022-01-24 14:22:54,606  ERROR pymapmanager.logger  logger.py handle_exception() line:88 -- Uncaught exception
Traceback (most recent call last):
  File "pymapmanager/pointAnnotations2.py", line 45, in <module>
    run()
  File "pymapmanager/pointAnnotations2.py", line 33, in run
    print('numAnnotations:', la.numAnnotations())
TypeError: 'int' object is not callable
2022-01-24 14:23:10,360  ERROR pymapmanager.logger  logger.py handle_exception() line:88 -- Uncaught exception
Traceback (most recent call last):
  File "pymapmanager/pointAnnotations2.py", line 45, in <module>
    run()
  File "pymapmanager/pointAnnotations2.py", line 34, in run
    xyz  = la.getPoints_xyz(asPixel=True)
  File "/home/cudmore/Sites/PyMapManager/pymapmanager/baseAnnotations.py", line 118, in getPoints_xyz
    print(self._voxelx, self._voxely)
AttributeError: 'pointAnnotations' object has no attribute '_voxelx'
2022-01-24 14:28:36,685  ERROR pymapmanager.logger  logger.py handle_exception() line:88 -- Uncaught exception
Traceback (most recent call last):
  File "pymapmanager/lineAnnotations.py", line 39, in <module>
    run()
  File "pymapmanager/lineAnnotations.py", line 26, in run
    la = lineAnnotations(stackBasePath)
  File "/home/cudmore/Sites/PyMapManager/pymapmanager/baseAnnotations.py", line 30, in __init__
    self._df = self.load()
  File "/home/cudmore/Sites/PyMapManager/pymapmanager/baseAnnotations.py", line 78, in load
    df = pd.read_csv(annotationPath, header=1, index_col=False)
  File "/home/cudmore/Sites/PyMapManager/mm_env/lib/python3.8/site-packages/pandas/util/_decorators.py", line 311, in wrapper
    return func(*args, **kwargs)
  File "/home/cudmore/Sites/PyMapManager/mm_env/lib/python3.8/site-packages/pandas/io/parsers/readers.py", line 586, in read_csv
    return _read(filepath_or_buffer, kwds)
  File "/home/cudmore/Sites/PyMapManager/mm_env/lib/python3.8/site-packages/pandas/io/parsers/readers.py", line 488, in _read
    return parser.read(nrows)
  File "/home/cudmore/Sites/PyMapManager/mm_env/lib/python3.8/site-packages/pandas/io/parsers/readers.py", line 1047, in read
    index, columns, col_dict = self._engine.read(nrows)
  File "/home/cudmore/Sites/PyMapManager/mm_env/lib/python3.8/site-packages/pandas/io/parsers/c_parser_wrapper.py", line 223, in read
    chunks = self._reader.read_low_memory(nrows)
  File "pandas/_libs/parsers.pyx", line 801, in pandas._libs.parsers.TextReader.read_low_memory
  File "pandas/_libs/parsers.pyx", line 857, in pandas._libs.parsers.TextReader._read_rows
  File "pandas/_libs/parsers.pyx", line 843, in pandas._libs.parsers.TextReader._tokenize_rows
  File "pandas/_libs/parsers.pyx", line 1925, in pandas._libs.parsers.raise_parser_error
pandas.errors.ParserError: Error tokenizing data. C error: Expected 17 fields in line 8, saw 22

2022-01-24 14:29:19,423  ERROR pymapmanager.logger  logger.py handle_exception() line:88 -- Uncaught exception
Traceback (most recent call last):
  File "pymapmanager/lineAnnotations.py", line 39, in <module>
    run()
  File "pymapmanager/lineAnnotations.py", line 26, in run
    la = lineAnnotations(stackBasePath)
  File "/home/cudmore/Sites/PyMapManager/pymapmanager/baseAnnotations.py", line 30, in __init__
    self._df = self.load()
  File "/home/cudmore/Sites/PyMapManager/pymapmanager/baseAnnotations.py", line 78, in load
    df = pd.read_csv(annotationPath, header=1, index_col=False)
  File "/home/cudmore/Sites/PyMapManager/mm_env/lib/python3.8/site-packages/pandas/util/_decorators.py", line 311, in wrapper
    return func(*args, **kwargs)
  File "/home/cudmore/Sites/PyMapManager/mm_env/lib/python3.8/site-packages/pandas/io/parsers/readers.py", line 586, in read_csv
    return _read(filepath_or_buffer, kwds)
  File "/home/cudmore/Sites/PyMapManager/mm_env/lib/python3.8/site-packages/pandas/io/parsers/readers.py", line 488, in _read
    return parser.read(nrows)
  File "/home/cudmore/Sites/PyMapManager/mm_env/lib/python3.8/site-packages/pandas/io/parsers/readers.py", line 1047, in read
    index, columns, col_dict = self._engine.read(nrows)
  File "/home/cudmore/Sites/PyMapManager/mm_env/lib/python3.8/site-packages/pandas/io/parsers/c_parser_wrapper.py", line 223, in read
    chunks = self._reader.read_low_memory(nrows)
  File "pandas/_libs/parsers.pyx", line 801, in pandas._libs.parsers.TextReader.read_low_memory
  File "pandas/_libs/parsers.pyx", line 857, in pandas._libs.parsers.TextReader._read_rows
  File "pandas/_libs/parsers.pyx", line 843, in pandas._libs.parsers.TextReader._tokenize_rows
  File "pandas/_libs/parsers.pyx", line 1925, in pandas._libs.parsers.raise_parser_error
pandas.errors.ParserError: Error tokenizing data. C error: Expected 17 fields in line 8, saw 22

2022-01-24 14:30:11,072  ERROR pymapmanager.logger  logger.py handle_exception() line:88 -- Uncaught exception
Traceback (most recent call last):
  File "/home/cudmore/Sites/PyMapManager/mm_env/lib/python3.8/site-packages/pandas/core/indexes/base.py", line 3361, in get_loc
    return self._engine.get_loc(casted_key)
  File "pandas/_libs/index.pyx", line 76, in pandas._libs.index.IndexEngine.get_loc
  File "pandas/_libs/index.pyx", line 108, in pandas._libs.index.IndexEngine.get_loc
  File "pandas/_libs/hashtable_class_helper.pxi", line 5198, in pandas._libs.hashtable.PyObjectHashTable.get_item
  File "pandas/_libs/hashtable_class_helper.pxi", line 5206, in pandas._libs.hashtable.PyObjectHashTable.get_item
KeyError: 'roiType'

The above exception was the direct cause of the following exception:

Traceback (most recent call last):
  File "pymapmanager/lineAnnotations.py", line 39, in <module>
    run()
  File "pymapmanager/lineAnnotations.py", line 28, in run
    xyz  = la.getPoints_xyz(asPixel=True)
  File "/home/cudmore/Sites/PyMapManager/pymapmanager/baseAnnotations.py", line 111, in getPoints_xyz
    df = df[df['roiType'].isin(roiType)]
  File "/home/cudmore/Sites/PyMapManager/mm_env/lib/python3.8/site-packages/pandas/core/frame.py", line 3458, in __getitem__
    indexer = self.columns.get_loc(key)
  File "/home/cudmore/Sites/PyMapManager/mm_env/lib/python3.8/site-packages/pandas/core/indexes/base.py", line 3363, in get_loc
    raise KeyError(key) from err
KeyError: 'roiType'
2022-01-24 14:31:39,858  WARNING pymapmanager.baseAnnotations  baseAnnotations.py getPoints_xyz() line:114 -- fix this difference between point and line annotations
2022-01-24 14:36:38,570  ERROR pymapmanager.logger  logger.py handle_exception() line:88 -- Uncaught exception
Traceback (most recent call last):
  File "pymapmanager/stack.py", line 398, in <module>
    run()
  File "pymapmanager/stack.py", line 354, in run
    myStack = stack(tifPath)
  File "pymapmanager/stack.py", line 79, in __init__
    imageShape = self.loadImages(channel=loadChannel)
  File "pymapmanager/stack.py", line 187, in loadImages
    logger.info(f'Loaded tif data {tifData.shape} from tif file: {tiffPath}')
NameError: name 'tiffPath' is not defined
2022-01-24 14:37:22,840   INFO __main__  stack.py loadImages() line:187 -- Loaded tif data (70, 1024, 1024) from tif file: /media/cudmore/data/richard/rr30a/firstMap/stacks/rr30a_s0_ch1.tif
2022-01-24 14:37:22,841   INFO __main__  stack.py loadHeader() line:160 -- Loading header /media/cudmore/data/richard/rr30a/firstMap/stacks/rr30a_s0/rr30a_s0.json
2022-01-24 14:37:22,848  ERROR pymapmanager.logger  logger.py handle_exception() line:88 -- Uncaught exception
Traceback (most recent call last):
  File "pymapmanager/stack.py", line 398, in <module>
    run()
  File "pymapmanager/stack.py", line 355, in run
    print(myStack)
  File "pymapmanager/stack.py", line 118, in __str__
    printList.append(f'segments: {self.getLineAnnotations().numSegments}')
AttributeError: 'lineAnnotations' object has no attribute 'numSegments'
2022-01-24 14:38:06,802   INFO __main__  stack.py loadImages() line:187 -- Loaded tif data (70, 1024, 1024) from tif file: /media/cudmore/data/richard/rr30a/firstMap/stacks/rr30a_s0_ch1.tif
2022-01-24 14:38:06,802   INFO __main__  stack.py loadHeader() line:160 -- Loading header /media/cudmore/data/richard/rr30a/firstMap/stacks/rr30a_s0/rr30a_s0.json
2022-01-24 14:38:06,809  ERROR pymapmanager.logger  logger.py handle_exception() line:88 -- Uncaught exception
Traceback (most recent call last):
  File "pymapmanager/stack.py", line 398, in <module>
    run()
  File "pymapmanager/stack.py", line 355, in run
    print(myStack)
  File "pymapmanager/stack.py", line 118, in __str__
    printList.append(f'segments: {self.getLineAnnotations().numSegments}')
  File "/home/cudmore/Sites/PyMapManager/pymapmanager/lineAnnotations.py", line 25, in numSegments
    parentList = self._dfLine['parentID'].unique()
AttributeError: 'lineAnnotations' object has no attribute '_dfLine'
2022-01-24 14:38:18,975   INFO __main__  stack.py loadImages() line:187 -- Loaded tif data (70, 1024, 1024) from tif file: /media/cudmore/data/richard/rr30a/firstMap/stacks/rr30a_s0_ch1.tif
2022-01-24 14:38:18,976   INFO __main__  stack.py loadHeader() line:160 -- Loading header /media/cudmore/data/richard/rr30a/firstMap/stacks/rr30a_s0/rr30a_s0.json
2022-01-24 14:38:18,983   INFO __main__  stack.py saveHeader() line:155 -- Saved header /media/cudmore/data/richard/rr30a/firstMap/stacks/rr30a_s0/rr30a_s0.json
2022-01-24 14:38:18,983  ERROR __main__  stack.py loadImages() line:181 -- Did not find tif file at /media/cudmore/data/richard/rr30a/firstMap/stacks/rr30a_s0_ch0.tif
2022-01-24 14:38:18,983  ERROR pymapmanager.logger  logger.py handle_exception() line:88 -- Uncaught exception
Traceback (most recent call last):
  File "pymapmanager/stack.py", line 398, in <module>
    run()
  File "pymapmanager/stack.py", line 366, in run
    maxProject1 = myStack.getMaxProject(channel=1)
  File "pymapmanager/stack.py", line 213, in getMaxProject
    return self._images[channelIdx].max(axis=self.imageSliceIdx)
AttributeError: 'NoneType' object has no attribute 'max'
2022-01-24 14:40:58,080   INFO __main__  stack.py loadImages() line:187 -- Loaded tif data (70, 1024, 1024) from tif file: /media/cudmore/data/richard/rr30a/firstMap/stacks/rr30a_s0_ch2.tif
2022-01-24 14:40:58,080   INFO __main__  stack.py loadHeader() line:160 -- Loading header /media/cudmore/data/richard/rr30a/firstMap/stacks/rr30a_s0/rr30a_s0.json
2022-01-24 14:40:58,088   INFO __main__  stack.py saveHeader() line:155 -- Saved header /media/cudmore/data/richard/rr30a/firstMap/stacks/rr30a_s0/rr30a_s0.json
2022-01-24 14:40:58,137   INFO __main__  stack.py loadImages() line:187 -- Loaded tif data (70, 1024, 1024) from tif file: /media/cudmore/data/richard/rr30a/firstMap/stacks/rr30a_s0_ch1.tif
2022-01-24 14:40:58,397  ERROR pymapmanager.logger  logger.py handle_exception() line:88 -- Uncaught exception
Traceback (most recent call last):
  File "pymapmanager/stack.py", line 398, in <module>
    run()
  File "pymapmanager/stack.py", line 389, in run
    pymapmanager.plotting.plottingUtils.plotMax(myStack, roiType=roiType, segmentID=segmentID)
  File "/home/cudmore/Sites/PyMapManager/pymapmanager/plotting/plottingUtils.py", line 37, in plotMax
    xyzLine = stack.getLineAnnotations().getLine(segmentID=segmentID, asPixel=False)
AttributeError: 'lineAnnotations' object has no attribute 'getLine'
2022-01-24 14:41:30,847   INFO __main__  stack.py loadImages() line:187 -- Loaded tif data (70, 1024, 1024) from tif file: /media/cudmore/data/richard/rr30a/firstMap/stacks/rr30a_s0_ch2.tif
2022-01-24 14:41:30,847   INFO __main__  stack.py loadHeader() line:160 -- Loading header /media/cudmore/data/richard/rr30a/firstMap/stacks/rr30a_s0/rr30a_s0.json
2022-01-24 14:41:30,855   INFO __main__  stack.py saveHeader() line:155 -- Saved header /media/cudmore/data/richard/rr30a/firstMap/stacks/rr30a_s0/rr30a_s0.json
2022-01-24 14:41:30,904   INFO __main__  stack.py loadImages() line:187 -- Loaded tif data (70, 1024, 1024) from tif file: /media/cudmore/data/richard/rr30a/firstMap/stacks/rr30a_s0_ch1.tif
2022-01-24 14:41:31,165  WARNING pymapmanager.baseAnnotations  baseAnnotations.py getPoints_xyz() line:114 -- fix this difference between point and line annotations
2022-01-24 14:44:51,934   INFO __main__  stack.py loadImages() line:187 -- Loaded tif data (70, 1024, 1024) from tif file: /media/cudmore/data/richard/rr30a/firstMap/stacks/rr30a_s0_ch2.tif
2022-01-24 14:44:51,935   INFO __main__  stack.py loadHeader() line:160 -- Loading header /media/cudmore/data/richard/rr30a/firstMap/stacks/rr30a_s0/rr30a_s0.json
2022-01-24 14:44:51,942   INFO __main__  stack.py saveHeader() line:155 -- Saved header /media/cudmore/data/richard/rr30a/firstMap/stacks/rr30a_s0/rr30a_s0.json
2022-01-24 14:44:51,991   INFO __main__  stack.py loadImages() line:187 -- Loaded tif data (70, 1024, 1024) from tif file: /media/cudmore/data/richard/rr30a/firstMap/stacks/rr30a_s0_ch1.tif
2022-01-24 14:44:52,251  WARNING pymapmanager.baseAnnotations  baseAnnotations.py getPoints_xyz() line:114 -- fix this difference between point and line annotations
2022-01-24 14:45:11,124   INFO __main__  stack.py loadImages() line:187 -- Loaded tif data (70, 1024, 1024) from tif file: /media/cudmore/data/richard/rr30a/firstMap/stacks/rr30a_s0_ch2.tif
2022-01-24 14:45:11,124   INFO __main__  stack.py loadHeader() line:160 -- Loading header /media/cudmore/data/richard/rr30a/firstMap/stacks/rr30a_s0/rr30a_s0.json
2022-01-24 14:45:11,132   INFO __main__  stack.py saveHeader() line:155 -- Saved header /media/cudmore/data/richard/rr30a/firstMap/stacks/rr30a_s0/rr30a_s0.json
2022-01-24 14:45:11,181   INFO __main__  stack.py loadImages() line:187 -- Loaded tif data (70, 1024, 1024) from tif file: /media/cudmore/data/richard/rr30a/firstMap/stacks/rr30a_s0_ch1.tif
2022-01-24 14:45:11,440  WARNING pymapmanager.baseAnnotations  baseAnnotations.py getPoints_xyz() line:114 -- fix this difference between point and line annotations
2022-01-24 14:45:11,442  WARNING pymapmanager.baseAnnotations  baseAnnotations.py getPoints_xyz() line:114 -- fix this difference between point and line annotations
2022-01-24 14:45:11,443  WARNING pymapmanager.baseAnnotations  baseAnnotations.py getPoints_xyz() line:114 -- fix this difference between point and line annotations
2022-01-24 14:45:11,444  WARNING pymapmanager.baseAnnotations  baseAnnotations.py getPoints_xyz() line:114 -- fix this difference between point and line annotations
2022-01-24 14:45:11,445  WARNING pymapmanager.baseAnnotations  baseAnnotations.py getPoints_xyz() line:114 -- fix this difference between point and line annotations
2022-01-24 14:45:31,906   INFO __main__  stack.py loadImages() line:187 -- Loaded tif data (70, 1024, 1024) from tif file: /media/cudmore/data/richard/rr30a/firstMap/stacks/rr30a_s0_ch2.tif
2022-01-24 14:45:31,906   INFO __main__  stack.py loadHeader() line:160 -- Loading header /media/cudmore/data/richard/rr30a/firstMap/stacks/rr30a_s0/rr30a_s0.json
2022-01-24 14:45:31,914   INFO __main__  stack.py saveHeader() line:155 -- Saved header /media/cudmore/data/richard/rr30a/firstMap/stacks/rr30a_s0/rr30a_s0.json
2022-01-24 14:45:31,964   INFO __main__  stack.py loadImages() line:187 -- Loaded tif data (70, 1024, 1024) from tif file: /media/cudmore/data/richard/rr30a/firstMap/stacks/rr30a_s0_ch1.tif
2022-01-24 14:45:32,224  WARNING pymapmanager.baseAnnotations  baseAnnotations.py getPoints_xyz() line:114 -- fix this difference between point and line annotations
2022-01-24 14:45:32,226  WARNING pymapmanager.baseAnnotations  baseAnnotations.py getPoints_xyz() line:114 -- fix this difference between point and line annotations
2022-01-24 14:45:32,226  ERROR pymapmanager.logger  logger.py handle_exception() line:88 -- Uncaught exception
Traceback (most recent call last):
  File "pymapmanager/stack.py", line 398, in <module>
    run()
  File "pymapmanager/stack.py", line 389, in run
    pymapmanager.plotting.plottingUtils.plotMax(myStack, roiType=roiType, segmentID=segmentID)
  File "/home/cudmore/Sites/PyMapManager/pymapmanager/plotting/plottingUtils.py", line 44, in plotMax
    xyzLine = stack.getLineAnnotations().getPoints_xyz(segmentID=oneSegmentID, asPixel=False)
  File "/home/cudmore/Sites/PyMapManager/pymapmanager/baseAnnotations.py", line 116, in getPoints_xyz
    df = df[df['parentID'].isin(segmentID)]
  File "/home/cudmore/Sites/PyMapManager/mm_env/lib/python3.8/site-packages/pandas/core/series.py", line 5025, in isin
    result = algorithms.isin(self._values, values)
  File "/home/cudmore/Sites/PyMapManager/mm_env/lib/python3.8/site-packages/pandas/core/algorithms.py", line 459, in isin
    raise TypeError(
TypeError: only list-like objects are allowed to be passed to isin(), you passed a [int]
2022-01-24 14:45:46,968   INFO __main__  stack.py loadImages() line:187 -- Loaded tif data (70, 1024, 1024) from tif file: /media/cudmore/data/richard/rr30a/firstMap/stacks/rr30a_s0_ch2.tif
2022-01-24 14:45:46,968   INFO __main__  stack.py loadHeader() line:160 -- Loading header /media/cudmore/data/richard/rr30a/firstMap/stacks/rr30a_s0/rr30a_s0.json
2022-01-24 14:45:46,976   INFO __main__  stack.py saveHeader() line:155 -- Saved header /media/cudmore/data/richard/rr30a/firstMap/stacks/rr30a_s0/rr30a_s0.json
2022-01-24 14:45:47,025   INFO __main__  stack.py loadImages() line:187 -- Loaded tif data (70, 1024, 1024) from tif file: /media/cudmore/data/richard/rr30a/firstMap/stacks/rr30a_s0_ch1.tif
2022-01-24 14:45:47,284  ERROR pymapmanager.logger  logger.py handle_exception() line:88 -- Uncaught exception
Traceback (most recent call last):
  File "pymapmanager/stack.py", line 398, in <module>
    run()
  File "pymapmanager/stack.py", line 389, in run
    pymapmanager.plotting.plottingUtils.plotMax(myStack, roiType=roiType, segmentID=segmentID)
  File "/home/cudmore/Sites/PyMapManager/pymapmanager/plotting/plottingUtils.py", line 43, in plotMax
    for [oneSegmentID] in segmentID:
TypeError: cannot unpack non-iterable int object
2022-01-24 14:46:05,983   INFO __main__  stack.py loadImages() line:187 -- Loaded tif data (70, 1024, 1024) from tif file: /media/cudmore/data/richard/rr30a/firstMap/stacks/rr30a_s0_ch2.tif
2022-01-24 14:46:05,983   INFO __main__  stack.py loadHeader() line:160 -- Loading header /media/cudmore/data/richard/rr30a/firstMap/stacks/rr30a_s0/rr30a_s0.json
2022-01-24 14:46:05,991   INFO __main__  stack.py saveHeader() line:155 -- Saved header /media/cudmore/data/richard/rr30a/firstMap/stacks/rr30a_s0/rr30a_s0.json
2022-01-24 14:46:06,043   INFO __main__  stack.py loadImages() line:187 -- Loaded tif data (70, 1024, 1024) from tif file: /media/cudmore/data/richard/rr30a/firstMap/stacks/rr30a_s0_ch1.tif
2022-01-24 14:46:06,319  WARNING pymapmanager.baseAnnotations  baseAnnotations.py getPoints_xyz() line:114 -- fix this difference between point and line annotations
2022-01-24 14:46:06,321  WARNING pymapmanager.baseAnnotations  baseAnnotations.py getPoints_xyz() line:114 -- fix this difference between point and line annotations
2022-01-24 14:46:06,322  WARNING pymapmanager.baseAnnotations  baseAnnotations.py getPoints_xyz() line:114 -- fix this difference between point and line annotations
2022-01-24 14:46:06,323  WARNING pymapmanager.baseAnnotations  baseAnnotations.py getPoints_xyz() line:114 -- fix this difference between point and line annotations
2022-01-24 14:46:06,324  WARNING pymapmanager.baseAnnotations  baseAnnotations.py getPoints_xyz() line:114 -- fix this difference between point and line annotations
2022-01-24 14:54:43,511  WARNING pymapmanager.baseAnnotations  baseAnnotations.py getPoints_xyz() line:114 -- fix this difference between point and line annotations
2022-01-24 14:54:43,511  ERROR pymapmanager.logger  logger.py handle_exception() line:88 -- Uncaught exception
Traceback (most recent call last):
  File "pymapmanager/lineAnnotations.py", line 78, in <module>
    run()
  File "pymapmanager/lineAnnotations.py", line 68, in run
    segLen = la.calculateSegmentLength()
  File "pymapmanager/lineAnnotations.py", line 38, in calculateSegmentLength
    for segment in range(self.numSegments()):
TypeError: 'int' object is not callable
2022-01-24 14:54:55,774  WARNING pymapmanager.baseAnnotations  baseAnnotations.py getPoints_xyz() line:114 -- fix this difference between point and line annotations
2022-01-24 14:54:55,775  WARNING pymapmanager.baseAnnotations  baseAnnotations.py getPoints_xyz() line:114 -- fix this difference between point and line annotations
2022-01-24 14:54:55,776  ERROR pymapmanager.logger  logger.py handle_exception() line:88 -- Uncaught exception
Traceback (most recent call last):
  File "pymapmanager/lineAnnotations.py", line 78, in <module>
    run()
  File "pymapmanager/lineAnnotations.py", line 68, in run
    segLen = la.calculateSegmentLength()
  File "pymapmanager/lineAnnotations.py", line 42, in calculateSegmentLength
    if prevPoint is not None:
UnboundLocalError: local variable 'prevPoint' referenced before assignment
2022-01-24 14:55:11,432  WARNING pymapmanager.baseAnnotations  baseAnnotations.py getPoints_xyz() line:114 -- fix this difference between point and line annotations
2022-01-24 14:55:11,432  WARNING pymapmanager.baseAnnotations  baseAnnotations.py getPoints_xyz() line:114 -- fix this difference between point and line annotations
2022-01-24 14:55:11,433  ERROR pymapmanager.logger  logger.py handle_exception() line:88 -- Uncaught exception
Traceback (most recent call last):
  File "pymapmanager/lineAnnotations.py", line 79, in <module>
    run()
  File "pymapmanager/lineAnnotations.py", line 69, in run
    segLen = la.calculateSegmentLength()
  File "pymapmanager/lineAnnotations.py", line 44, in calculateSegmentLength
    xPrev = prevPoint[idx,0]
IndexError: too many indices for array: array is 1-dimensional, but 2 were indexed
2022-01-24 14:56:13,752  WARNING pymapmanager.baseAnnotations  baseAnnotations.py getPoints_xyz() line:114 -- fix this difference between point and line annotations
2022-01-24 14:56:13,753  WARNING pymapmanager.baseAnnotations  baseAnnotations.py getPoints_xyz() line:114 -- fix this difference between point and line annotations
2022-01-24 14:56:13,754  ERROR pymapmanager.logger  logger.py handle_exception() line:88 -- Uncaught exception
Traceback (most recent call last):
  File "pymapmanager/lineAnnotations.py", line 79, in <module>
    run()
  File "pymapmanager/lineAnnotations.py", line 69, in run
    segLen = la.calculateSegmentLength()
  File "pymapmanager/lineAnnotations.py", line 56, in calculateSegmentLength
    distToPrev2D = sqrt(dx**2 + dy**2)
NameError: name 'sqrt' is not defined
2022-01-24 14:56:42,529  WARNING pymapmanager.baseAnnotations  baseAnnotations.py getPoints_xyz() line:114 -- fix this difference between point and line annotations
2022-01-24 14:56:42,530  WARNING pymapmanager.baseAnnotations  baseAnnotations.py getPoints_xyz() line:114 -- fix this difference between point and line annotations
2022-01-24 14:56:42,531  WARNING pymapmanager.baseAnnotations  baseAnnotations.py getPoints_xyz() line:114 -- fix this difference between point and line annotations
2022-01-24 14:56:42,532  WARNING pymapmanager.baseAnnotations  baseAnnotations.py getPoints_xyz() line:114 -- fix this difference between point and line annotations
2022-01-24 14:56:42,533  WARNING pymapmanager.baseAnnotations  baseAnnotations.py getPoints_xyz() line:114 -- fix this difference between point and line annotations
2022-01-24 14:56:42,534  WARNING pymapmanager.baseAnnotations  baseAnnotations.py getPoints_xyz() line:114 -- fix this difference between point and line annotations
2022-01-24 14:56:59,017  WARNING pymapmanager.baseAnnotations  baseAnnotations.py getPoints_xyz() line:114 -- fix this difference between point and line annotations
2022-01-24 14:56:59,017  WARNING pymapmanager.baseAnnotations  baseAnnotations.py getPoints_xyz() line:114 -- fix this difference between point and line annotations
2022-01-24 14:56:59,019  WARNING pymapmanager.baseAnnotations  baseAnnotations.py getPoints_xyz() line:114 -- fix this difference between point and line annotations
2022-01-24 14:56:59,020  WARNING pymapmanager.baseAnnotations  baseAnnotations.py getPoints_xyz() line:114 -- fix this difference between point and line annotations
2022-01-24 14:56:59,021  WARNING pymapmanager.baseAnnotations  baseAnnotations.py getPoints_xyz() line:114 -- fix this difference between point and line annotations
2022-01-24 14:56:59,021  WARNING pymapmanager.baseAnnotations  baseAnnotations.py getPoints_xyz() line:114 -- fix this difference between point and line annotations
2022-01-24 15:01:56,657  WARNING pymapmanager.baseAnnotations  baseAnnotations.py getPoints_xyz() line:114 -- fix this difference between point and line annotations
2022-01-24 15:01:56,657  WARNING pymapmanager.baseAnnotations  baseAnnotations.py getPoints_xyz() line:114 -- fix this difference between point and line annotations
2022-01-24 15:01:56,659  WARNING pymapmanager.baseAnnotations  baseAnnotations.py getPoints_xyz() line:114 -- fix this difference between point and line annotations
2022-01-24 15:01:56,660  WARNING pymapmanager.baseAnnotations  baseAnnotations.py getPoints_xyz() line:114 -- fix this difference between point and line annotations
2022-01-24 15:01:56,662  WARNING pymapmanager.baseAnnotations  baseAnnotations.py getPoints_xyz() line:114 -- fix this difference between point and line annotations
2022-01-24 15:01:56,663  WARNING pymapmanager.baseAnnotations  baseAnnotations.py getPoints_xyz() line:114 -- fix this difference between point and line annotations
2022-01-24 15:01:56,664  ERROR pymapmanager.logger  logger.py handle_exception() line:88 -- Uncaught exception
Traceback (most recent call last):
  File "pymapmanager/lineAnnotations.py", line 84, in <module>
    run()
  File "pymapmanager/lineAnnotations.py", line 74, in run
    segLen = la.calculateSegmentLength()
  File "pymapmanager/lineAnnotations.py", line 66, in calculateSegmentLength
    return lengthList
NameError: name 'lengthList' is not defined
2022-01-24 15:02:21,642  WARNING pymapmanager.baseAnnotations  baseAnnotations.py getPoints_xyz() line:114 -- fix this difference between point and line annotations
2022-01-24 15:02:21,643  WARNING pymapmanager.baseAnnotations  baseAnnotations.py getPoints_xyz() line:114 -- fix this difference between point and line annotations
2022-01-24 15:02:21,645  WARNING pymapmanager.baseAnnotations  baseAnnotations.py getPoints_xyz() line:114 -- fix this difference between point and line annotations
2022-01-24 15:02:21,647  WARNING pymapmanager.baseAnnotations  baseAnnotations.py getPoints_xyz() line:114 -- fix this difference between point and line annotations
2022-01-24 15:02:21,648  WARNING pymapmanager.baseAnnotations  baseAnnotations.py getPoints_xyz() line:114 -- fix this difference between point and line annotations
2022-01-24 15:02:21,649  WARNING pymapmanager.baseAnnotations  baseAnnotations.py getPoints_xyz() line:114 -- fix this difference between point and line annotations
2022-01-24 15:19:20,897   INFO __main__  stack.py loadImages() line:187 -- Loaded tif data (70, 1024, 1024) from tif file: /media/cudmore/data/richard/rr30a/naked-tif/rr30a_s0_ch2.tif
2022-01-24 15:19:20,897  WARNING __main__  stack.py loadHeader() line:165 -- Did not find header file /media/cudmore/data/richard/rr30a/naked-tif/rr30a_s0/rr30a_s0.json
2022-01-24 15:19:20,897   INFO __main__  stack.py __init__() line:84 -- Creating header
2022-01-24 15:19:20,897  ERROR pymapmanager.baseAnnotations  baseAnnotations.py load() line:77 -- Did not find annotation file: /media/cudmore/data/richard/rr30a/naked-tif/rr30a_s0/rr30a_s0_db2.txt
2022-01-24 15:19:20,897  ERROR pymapmanager.logger  logger.py handle_exception() line:88 -- Uncaught exception
Traceback (most recent call last):
  File "pymapmanager/stack.py", line 403, in <module>
    run()
  File "pymapmanager/stack.py", line 353, in run
    myStack = stack(nakedPath)
  File "pymapmanager/stack.py", line 102, in __init__
    self.loadAnnotations()
  File "pymapmanager/stack.py", line 249, in loadAnnotations
    self._annotations = pymapmanager.pointAnnotations.pointAnnotations(self._basePath)
  File "/home/cudmore/Sites/PyMapManager/pymapmanager/baseAnnotations.py", line 30, in __init__
    self._df = self.load()
  File "/home/cudmore/Sites/PyMapManager/pymapmanager/baseAnnotations.py", line 78, in load
    raise OSError(errno.ENOENT, os.strerror(errno.ENOENT), annotationPath)
NameError: name 'errno' is not defined
2022-01-24 15:20:14,508   INFO __main__  stack.py loadImages() line:187 -- Loaded tif data (70, 1024, 1024) from tif file: /media/cudmore/data/richard/rr30a/naked-tif/rr30a_s0_ch2.tif
2022-01-24 15:20:14,509  WARNING __main__  stack.py loadHeader() line:165 -- Did not find header file /media/cudmore/data/richard/rr30a/naked-tif/rr30a_s0/rr30a_s0.json
2022-01-24 15:20:14,509   INFO __main__  stack.py __init__() line:84 -- Creating header
2022-01-24 15:20:14,509  ERROR pymapmanager.baseAnnotations  baseAnnotations.py load() line:78 -- Did not find annotation file: /media/cudmore/data/richard/rr30a/naked-tif/rr30a_s0/rr30a_s0_db2.txt
2022-01-24 15:20:14,510  ERROR pymapmanager.baseAnnotations  baseAnnotations.py load() line:78 -- Did not find annotation file: /media/cudmore/data/richard/rr30a/naked-tif/rr30a_s0/rr30a_s0_l.txt
2022-01-24 15:21:48,354   INFO __main__  stack.py loadImages() line:187 -- Loaded tif data (70, 1024, 1024) from tif file: /media/cudmore/data/richard/rr30a/naked-tif/rr30a_s0_ch2.tif
2022-01-24 15:21:48,354  WARNING __main__  stack.py loadHeader() line:165 -- Did not find header file /media/cudmore/data/richard/rr30a/naked-tif/rr30a_s0/rr30a_s0.json
2022-01-24 15:21:48,354   INFO __main__  stack.py __init__() line:84 -- Creating header
2022-01-24 15:21:48,354  ERROR pymapmanager.baseAnnotations  baseAnnotations.py load() line:81 -- Did not find annotation file: /media/cudmore/data/richard/rr30a/naked-tif/rr30a_s0/rr30a_s0_db2.txt
2022-01-24 15:21:48,356  ERROR pymapmanager.baseAnnotations  baseAnnotations.py load() line:81 -- Did not find annotation file: /media/cudmore/data/richard/rr30a/naked-tif/rr30a_s0/rr30a_s0_l.txt
2022-01-24 15:30:20,312   INFO __main__  stack.py loadImages() line:187 -- Loaded tif data (70, 1024, 1024) from tif file: /media/cudmore/data/richard/rr30a/naked-tif/rr30a_s0_ch2.tif
2022-01-24 15:30:20,312  WARNING __main__  stack.py loadHeader() line:165 -- Did not find header file /media/cudmore/data/richard/rr30a/naked-tif/rr30a_s0/rr30a_s0.json
2022-01-24 15:30:20,312   INFO __main__  stack.py __init__() line:84 -- Creating header
2022-01-24 15:30:20,312  ERROR pymapmanager.baseAnnotations  baseAnnotations.py load() line:90 -- Did not find annotation file: /media/cudmore/data/richard/rr30a/naked-tif/rr30a_s0/rr30a_s0_db2.txt
2022-01-24 15:30:20,314  ERROR pymapmanager.baseAnnotations  baseAnnotations.py load() line:90 -- Did not find annotation file: /media/cudmore/data/richard/rr30a/naked-tif/rr30a_s0/rr30a_s0_l.txt
2022-01-24 15:30:20,316  ERROR pymapmanager.logger  logger.py handle_exception() line:88 -- Uncaught exception
Traceback (most recent call last):
  File "pymapmanager/stack.py", line 407, in <module>
    run()
  File "pymapmanager/stack.py", line 358, in run
    myStack.getPointAnnotations().addAnnotation(x=10, y=20, z=30)
  File "/home/cudmore/Sites/PyMapManager/pymapmanager/pointAnnotations.py", line 31, in addAnnotation
    super(pointAnnotations, self).__init__(*args,**kwargs)
TypeError: __init__() got an unexpected keyword argument 'x'
2022-01-24 15:30:51,176   INFO __main__  stack.py loadImages() line:187 -- Loaded tif data (70, 1024, 1024) from tif file: /media/cudmore/data/richard/rr30a/naked-tif/rr30a_s0_ch2.tif
2022-01-24 15:30:51,176  WARNING __main__  stack.py loadHeader() line:165 -- Did not find header file /media/cudmore/data/richard/rr30a/naked-tif/rr30a_s0/rr30a_s0.json
2022-01-24 15:30:51,176   INFO __main__  stack.py __init__() line:84 -- Creating header
2022-01-24 15:30:51,176  ERROR pymapmanager.baseAnnotations  baseAnnotations.py load() line:90 -- Did not find annotation file: /media/cudmore/data/richard/rr30a/naked-tif/rr30a_s0/rr30a_s0_db2.txt
2022-01-24 15:30:51,178  ERROR pymapmanager.baseAnnotations  baseAnnotations.py load() line:90 -- Did not find annotation file: /media/cudmore/data/richard/rr30a/naked-tif/rr30a_s0/rr30a_s0_l.txt
2022-01-24 15:30:51,180  ERROR pymapmanager.logger  logger.py handle_exception() line:88 -- Uncaught exception
Traceback (most recent call last):
  File "pymapmanager/stack.py", line 407, in <module>
    run()
  File "pymapmanager/stack.py", line 358, in run
    myStack.getPointAnnotations().addAnnotation(xPnt=10, yPnt=20, zPnt=30)
  File "/home/cudmore/Sites/PyMapManager/pymapmanager/pointAnnotations.py", line 31, in addAnnotation
    super(pointAnnotations, self).__init__(*args,**kwargs)
TypeError: __init__() got an unexpected keyword argument 'xPnt'
2022-01-24 15:31:34,040   INFO __main__  stack.py loadImages() line:187 -- Loaded tif data (70, 1024, 1024) from tif file: /media/cudmore/data/richard/rr30a/naked-tif/rr30a_s0_ch2.tif
2022-01-24 15:31:34,041  WARNING __main__  stack.py loadHeader() line:165 -- Did not find header file /media/cudmore/data/richard/rr30a/naked-tif/rr30a_s0/rr30a_s0.json
2022-01-24 15:31:34,041   INFO __main__  stack.py __init__() line:84 -- Creating header
2022-01-24 15:31:34,041  ERROR pymapmanager.baseAnnotations  baseAnnotations.py load() line:90 -- Did not find annotation file: /media/cudmore/data/richard/rr30a/naked-tif/rr30a_s0/rr30a_s0_db2.txt
2022-01-24 15:31:34,042  ERROR pymapmanager.baseAnnotations  baseAnnotations.py load() line:90 -- Did not find annotation file: /media/cudmore/data/richard/rr30a/naked-tif/rr30a_s0/rr30a_s0_l.txt
2022-01-24 15:32:05,550   INFO __main__  stack.py loadImages() line:187 -- Loaded tif data (70, 1024, 1024) from tif file: /media/cudmore/data/richard/rr30a/naked-tif/rr30a_s0_ch2.tif
2022-01-24 15:32:05,550  WARNING __main__  stack.py loadHeader() line:165 -- Did not find header file /media/cudmore/data/richard/rr30a/naked-tif/rr30a_s0/rr30a_s0.json
2022-01-24 15:32:05,550   INFO __main__  stack.py __init__() line:84 -- Creating header
2022-01-24 15:32:05,550  ERROR pymapmanager.baseAnnotations  baseAnnotations.py load() line:90 -- Did not find annotation file: /media/cudmore/data/richard/rr30a/naked-tif/rr30a_s0/rr30a_s0_db2.txt
2022-01-24 15:32:05,552  ERROR pymapmanager.baseAnnotations  baseAnnotations.py load() line:90 -- Did not find annotation file: /media/cudmore/data/richard/rr30a/naked-tif/rr30a_s0/rr30a_s0_l.txt
2022-01-24 15:33:29,725   INFO __main__  stack.py loadImages() line:187 -- Loaded tif data (70, 1024, 1024) from tif file: /media/cudmore/data/richard/rr30a/naked-tif/rr30a_s0_ch2.tif
2022-01-24 15:33:29,725  WARNING __main__  stack.py loadHeader() line:165 -- Did not find header file /media/cudmore/data/richard/rr30a/naked-tif/rr30a_s0/rr30a_s0.json
2022-01-24 15:33:29,725   INFO __main__  stack.py __init__() line:84 -- Creating header
2022-01-24 15:33:29,725  ERROR pymapmanager.baseAnnotations  baseAnnotations.py load() line:94 -- Did not find annotation file: /media/cudmore/data/richard/rr30a/naked-tif/rr30a_s0/rr30a_s0_db2.txt
2022-01-24 15:33:29,727  ERROR pymapmanager.baseAnnotations  baseAnnotations.py load() line:94 -- Did not find annotation file: /media/cudmore/data/richard/rr30a/naked-tif/rr30a_s0/rr30a_s0_l.txt
2022-01-24 15:35:09,701   INFO __main__  stack.py loadImages() line:187 -- Loaded tif data (70, 1024, 1024) from tif file: /media/cudmore/data/richard/rr30a/naked-tif/rr30a_s0_ch2.tif
2022-01-24 15:35:09,701  WARNING __main__  stack.py loadHeader() line:165 -- Did not find header file /media/cudmore/data/richard/rr30a/naked-tif/rr30a_s0/rr30a_s0.json
2022-01-24 15:35:09,701   INFO __main__  stack.py __init__() line:84 -- Creating header
2022-01-24 15:35:09,701  ERROR pymapmanager.baseAnnotations  baseAnnotations.py load() line:99 -- Did not find annotation file: /media/cudmore/data/richard/rr30a/naked-tif/rr30a_s0/rr30a_s0_db2.txt
2022-01-24 15:35:09,703  ERROR pymapmanager.baseAnnotations  baseAnnotations.py load() line:99 -- Did not find annotation file: /media/cudmore/data/richard/rr30a/naked-tif/rr30a_s0/rr30a_s0_l.txt
2022-01-24 15:36:54,780   INFO __main__  stack.py loadImages() line:187 -- Loaded tif data (70, 1024, 1024) from tif file: /media/cudmore/data/richard/rr30a/naked-tif/rr30a_s0_ch2.tif
2022-01-24 15:36:54,781  WARNING __main__  stack.py loadHeader() line:165 -- Did not find header file /media/cudmore/data/richard/rr30a/naked-tif/rr30a_s0/rr30a_s0.json
2022-01-24 15:36:54,781   INFO __main__  stack.py __init__() line:84 -- Creating header
2022-01-24 15:36:54,781  ERROR pymapmanager.baseAnnotations  baseAnnotations.py load() line:101 -- Did not find annotation file: /media/cudmore/data/richard/rr30a/naked-tif/rr30a_s0/rr30a_s0_db2.txt
2022-01-24 15:36:54,782  ERROR pymapmanager.baseAnnotations  baseAnnotations.py load() line:101 -- Did not find annotation file: /media/cudmore/data/richard/rr30a/naked-tif/rr30a_s0/rr30a_s0_l.txt
2022-01-24 15:37:30,595   INFO __main__  stack.py loadImages() line:187 -- Loaded tif data (70, 1024, 1024) from tif file: /media/cudmore/data/richard/rr30a/naked-tif/rr30a_s0_ch2.tif
2022-01-24 15:37:30,596  WARNING __main__  stack.py loadHeader() line:165 -- Did not find header file /media/cudmore/data/richard/rr30a/naked-tif/rr30a_s0/rr30a_s0.json
2022-01-24 15:37:30,596   INFO __main__  stack.py __init__() line:84 -- Creating header
2022-01-24 15:37:30,596  ERROR pymapmanager.baseAnnotations  baseAnnotations.py load() line:101 -- Did not find annotation file: /media/cudmore/data/richard/rr30a/naked-tif/rr30a_s0/rr30a_s0_db2.txt
2022-01-24 15:37:30,597  ERROR pymapmanager.baseAnnotations  baseAnnotations.py load() line:101 -- Did not find annotation file: /media/cudmore/data/richard/rr30a/naked-tif/rr30a_s0/rr30a_s0_l.txt
2022-01-24 15:37:49,744   INFO __main__  stack.py loadImages() line:187 -- Loaded tif data (70, 1024, 1024) from tif file: /media/cudmore/data/richard/rr30a/naked-tif/rr30a_s0_ch2.tif
2022-01-24 15:37:49,745  WARNING __main__  stack.py loadHeader() line:165 -- Did not find header file /media/cudmore/data/richard/rr30a/naked-tif/rr30a_s0/rr30a_s0.json
2022-01-24 15:37:49,745   INFO __main__  stack.py __init__() line:84 -- Creating header
2022-01-24 15:37:49,745  ERROR pymapmanager.baseAnnotations  baseAnnotations.py load() line:101 -- Did not find annotation file: /media/cudmore/data/richard/rr30a/naked-tif/rr30a_s0/rr30a_s0_db2.txt
2022-01-24 15:37:49,746  ERROR pymapmanager.baseAnnotations  baseAnnotations.py load() line:101 -- Did not find annotation file: /media/cudmore/data/richard/rr30a/naked-tif/rr30a_s0/rr30a_s0_l.txt
2022-01-24 15:43:02,767  ERROR pymapmanager.logger  logger.py handle_exception() line:88 -- Uncaught exception
Traceback (most recent call last):
  File "pymapmanager/stack.py", line 10, in <module>
    import pymapmanager.pointAnnotations
  File "/home/cudmore/Sites/PyMapManager/pymapmanager/pointAnnotations.py", line 6, in <module>
    import pymapmanager.baseAnnotations
  File "/home/cudmore/Sites/PyMapManager/pymapmanager/baseAnnotations.py", line 13, in <module>
    class roiTypesClass(Enum):
NameError: name 'Enum' is not defined
2022-01-24 15:43:44,399  ERROR pymapmanager.logger  logger.py handle_exception() line:88 -- Uncaught exception
Traceback (most recent call last):
  File "pymapmanager/lineAnnotations.py", line 5, in <module>
    import pymapmanager.baseAnnotations
  File "/home/cudmore/Sites/PyMapManager/pymapmanager/baseAnnotations.py", line 21, in <module>
    class baseAnnotations():
  File "/home/cudmore/Sites/PyMapManager/pymapmanager/baseAnnotations.py", line 23, in baseAnnotations
    roiTypeEnum = roiTypesClass()
TypeError: __call__() missing 1 required positional argument: 'value'
2022-01-24 15:44:01,083  WARNING pymapmanager.baseAnnotations  baseAnnotations.py getPoints_xyz() line:151 -- fix this difference between point and line annotations
2022-01-24 15:44:01,084  WARNING pymapmanager.baseAnnotations  baseAnnotations.py getPoints_xyz() line:151 -- fix this difference between point and line annotations
2022-01-24 15:44:01,086  WARNING pymapmanager.baseAnnotations  baseAnnotations.py getPoints_xyz() line:151 -- fix this difference between point and line annotations
2022-01-24 15:44:01,087  WARNING pymapmanager.baseAnnotations  baseAnnotations.py getPoints_xyz() line:151 -- fix this difference between point and line annotations
2022-01-24 15:44:01,088  WARNING pymapmanager.baseAnnotations  baseAnnotations.py getPoints_xyz() line:151 -- fix this difference between point and line annotations
2022-01-24 15:44:01,089  WARNING pymapmanager.baseAnnotations  baseAnnotations.py getPoints_xyz() line:151 -- fix this difference between point and line annotations
2022-01-24 15:44:25,538   INFO __main__  stack.py loadImages() line:187 -- Loaded tif data (70, 1024, 1024) from tif file: /media/cudmore/data/richard/rr30a/naked-tif/rr30a_s0_ch2.tif
2022-01-24 15:44:25,538  WARNING __main__  stack.py loadHeader() line:165 -- Did not find header file /media/cudmore/data/richard/rr30a/naked-tif/rr30a_s0/rr30a_s0.json
2022-01-24 15:44:25,538   INFO __main__  stack.py __init__() line:84 -- Creating header
2022-01-24 15:44:25,538  ERROR pymapmanager.baseAnnotations  baseAnnotations.py load() line:111 -- Did not find annotation file: /media/cudmore/data/richard/rr30a/naked-tif/rr30a_s0/rr30a_s0_db2.txt
2022-01-24 15:44:25,539  ERROR pymapmanager.baseAnnotations  baseAnnotations.py load() line:111 -- Did not find annotation file: /media/cudmore/data/richard/rr30a/naked-tif/rr30a_s0/rr30a_s0_l.txt
2022-01-24 15:44:25,541  ERROR pymapmanager.logger  logger.py handle_exception() line:88 -- Uncaught exception
Traceback (most recent call last):
  File "pymapmanager/stack.py", line 414, in <module>
    run()
  File "pymapmanager/stack.py", line 359, in run
    spineROI = pymapmanager.baseAnnotations.roiTypeEnum.spineROI
AttributeError: module 'pymapmanager.baseAnnotations' has no attribute 'roiTypeEnum'
2022-01-24 15:45:04,796   INFO __main__  stack.py loadImages() line:187 -- Loaded tif data (70, 1024, 1024) from tif file: /media/cudmore/data/richard/rr30a/naked-tif/rr30a_s0_ch2.tif
2022-01-24 15:45:04,796  WARNING __main__  stack.py loadHeader() line:165 -- Did not find header file /media/cudmore/data/richard/rr30a/naked-tif/rr30a_s0/rr30a_s0.json
2022-01-24 15:45:04,796   INFO __main__  stack.py __init__() line:84 -- Creating header
2022-01-24 15:45:04,796  ERROR pymapmanager.baseAnnotations  baseAnnotations.py load() line:111 -- Did not find annotation file: /media/cudmore/data/richard/rr30a/naked-tif/rr30a_s0/rr30a_s0_db2.txt
2022-01-24 15:45:04,797  ERROR pymapmanager.baseAnnotations  baseAnnotations.py load() line:111 -- Did not find annotation file: /media/cudmore/data/richard/rr30a/naked-tif/rr30a_s0/rr30a_s0_l.txt
2022-01-24 16:43:24,153   INFO __main__  stack.py loadImages() line:197 -- Loaded tif data (70, 1024, 1024) from tif file: /media/cudmore/data/richard/rr30a/naked-tif/rr30a_s0_ch2.tif
2022-01-24 16:43:24,153  WARNING __main__  stack.py loadHeader() line:165 -- Did not find header file /media/cudmore/data/richard/rr30a/naked-tif/rr30a_s0/rr30a_s0.json
2022-01-24 16:43:24,153   INFO __main__  stack.py __init__() line:84 -- Creating header
2022-01-24 16:43:24,153  ERROR pymapmanager.baseAnnotations  baseAnnotations.py load() line:122 -- Did not find annotation file: /media/cudmore/data/richard/rr30a/naked-tif/rr30a_s0/rr30a_s0_db2.txt
2022-01-24 16:43:24,154  ERROR pymapmanager.baseAnnotations  baseAnnotations.py load() line:122 -- Did not find annotation file: /media/cudmore/data/richard/rr30a/naked-tif/rr30a_s0/rr30a_s0_l.txt
2022-01-24 16:43:24,165  ERROR pymapmanager.logger  logger.py handle_exception() line:88 -- Uncaught exception
Traceback (most recent call last):
  File "pymapmanager/stack.py", line 427, in <module>
    run()
  File "pymapmanager/stack.py", line 378, in run
    myStack.save()
  File "pymapmanager/stack.py", line 172, in save
    self.getLineAnnotations.save()
AttributeError: 'function' object has no attribute 'save'
2022-01-24 16:43:33,454   INFO __main__  stack.py loadImages() line:197 -- Loaded tif data (70, 1024, 1024) from tif file: /media/cudmore/data/richard/rr30a/naked-tif/rr30a_s0_ch2.tif
2022-01-24 16:43:33,454  WARNING __main__  stack.py loadHeader() line:165 -- Did not find header file /media/cudmore/data/richard/rr30a/naked-tif/rr30a_s0/rr30a_s0.json
2022-01-24 16:43:33,455   INFO __main__  stack.py __init__() line:84 -- Creating header
2022-01-24 16:43:33,455  ERROR pymapmanager.baseAnnotations  baseAnnotations.py load() line:122 -- Did not find annotation file: /media/cudmore/data/richard/rr30a/naked-tif/rr30a_s0/rr30a_s0_db2.txt
2022-01-24 16:43:33,456  ERROR pymapmanager.baseAnnotations  baseAnnotations.py load() line:122 -- Did not find annotation file: /media/cudmore/data/richard/rr30a/naked-tif/rr30a_s0/rr30a_s0_l.txt
2022-01-24 16:43:33,467  ERROR pymapmanager.logger  logger.py handle_exception() line:88 -- Uncaught exception
Traceback (most recent call last):
  File "pymapmanager/stack.py", line 427, in <module>
    run()
  File "pymapmanager/stack.py", line 378, in run
    myStack.save()
  File "pymapmanager/stack.py", line 172, in save
    self.getLineAnnotations.save()
AttributeError: 'function' object has no attribute 'save'
2022-01-24 16:44:03,152   INFO __main__  stack.py loadImages() line:197 -- Loaded tif data (70, 1024, 1024) from tif file: /media/cudmore/data/richard/rr30a/naked-tif/rr30a_s0_ch2.tif
2022-01-24 16:44:03,152  WARNING __main__  stack.py loadHeader() line:165 -- Did not find header file /media/cudmore/data/richard/rr30a/naked-tif/rr30a_s0/rr30a_s0.json
2022-01-24 16:44:03,152   INFO __main__  stack.py __init__() line:84 -- Creating header
2022-01-24 16:44:03,153  ERROR pymapmanager.baseAnnotations  baseAnnotations.py load() line:122 -- Did not find annotation file: /media/cudmore/data/richard/rr30a/naked-tif/rr30a_s0/rr30a_s0_db2.txt
2022-01-24 16:44:03,154  ERROR pymapmanager.baseAnnotations  baseAnnotations.py load() line:122 -- Did not find annotation file: /media/cudmore/data/richard/rr30a/naked-tif/rr30a_s0/rr30a_s0_l.txt
2022-01-24 16:44:03,164  ERROR pymapmanager.logger  logger.py handle_exception() line:88 -- Uncaught exception
Traceback (most recent call last):
  File "pymapmanager/stack.py", line 427, in <module>
    run()
  File "pymapmanager/stack.py", line 378, in run
    myStack.save()
  File "pymapmanager/stack.py", line 172, in save
    self.getLineAnnotations().save()
  File "/home/cudmore/Sites/PyMapManager/pymapmanager/baseAnnotations.py", line 137, in save
    with open(annotationPath, 'a') as file:
FileNotFoundError: [Errno 2] No such file or directory: '/media/cudmore/data/richard/rr30a/naked-tif/rr30a_s0/rr30a_s0_l.txt'
2022-01-24 16:45:20,659   INFO __main__  stack.py loadImages() line:201 -- Loaded tif data (70, 1024, 1024) from tif file: /media/cudmore/data/richard/rr30a/naked-tif/rr30a_s0_ch2.tif
2022-01-24 16:45:20,659  WARNING __main__  stack.py loadHeader() line:167 -- Did not find header file /media/cudmore/data/richard/rr30a/naked-tif/rr30a_s0/rr30a_s0.json
2022-01-24 16:45:20,659   INFO __main__  stack.py __init__() line:84 -- Creating header
2022-01-24 16:45:20,659  ERROR pymapmanager.baseAnnotations  baseAnnotations.py load() line:122 -- Did not find annotation file: /media/cudmore/data/richard/rr30a/naked-tif/rr30a_s0/rr30a_s0_db2.txt
2022-01-24 16:45:20,661  ERROR pymapmanager.baseAnnotations  baseAnnotations.py load() line:122 -- Did not find annotation file: /media/cudmore/data/richard/rr30a/naked-tif/rr30a_s0/rr30a_s0_l.txt
2022-01-24 16:45:20,672  ERROR pymapmanager.logger  logger.py handle_exception() line:88 -- Uncaught exception
Traceback (most recent call last):
  File "pymapmanager/stack.py", line 431, in <module>
    run()
  File "pymapmanager/stack.py", line 382, in run
    myStack.save()
  File "pymapmanager/stack.py", line 174, in save
    self._makeFolder()
  File "pymapmanager/stack.py", line 345, in _makeFolder
    baseName = self._getBaseName()
AttributeError: 'stack' object has no attribute '_getBaseName'
2022-01-24 16:46:43,920   INFO __main__  stack.py loadImages() line:201 -- Loaded tif data (70, 1024, 1024) from tif file: /media/cudmore/data/richard/rr30a/naked-tif/rr30a_s0_ch2.tif
2022-01-24 16:46:43,921  WARNING __main__  stack.py loadHeader() line:167 -- Did not find header file /media/cudmore/data/richard/rr30a/naked-tif/rr30a_s0/rr30a_s0.json
2022-01-24 16:46:43,921   INFO __main__  stack.py __init__() line:84 -- Creating header
2022-01-24 16:46:43,921  ERROR pymapmanager.baseAnnotations  baseAnnotations.py load() line:122 -- Did not find annotation file: /media/cudmore/data/richard/rr30a/naked-tif/rr30a_s0/rr30a_s0_db2.txt
2022-01-24 16:46:43,922  ERROR pymapmanager.baseAnnotations  baseAnnotations.py load() line:122 -- Did not find annotation file: /media/cudmore/data/richard/rr30a/naked-tif/rr30a_s0/rr30a_s0_l.txt
2022-01-24 16:46:43,933  ERROR pymapmanager.logger  logger.py handle_exception() line:88 -- Uncaught exception
Traceback (most recent call last):
  File "pymapmanager/stack.py", line 431, in <module>
    run()
  File "pymapmanager/stack.py", line 382, in run
    myStack.save()
  File "pymapmanager/stack.py", line 174, in save
    self._makeFolder()
  File "pymapmanager/stack.py", line 346, in _makeFolder
    if os.path.isdir(baseName):
NameError: name 'baseName' is not defined
2022-01-24 16:47:11,817   INFO __main__  stack.py loadImages() line:201 -- Loaded tif data (70, 1024, 1024) from tif file: /media/cudmore/data/richard/rr30a/naked-tif/rr30a_s0_ch2.tif
2022-01-24 16:47:11,817  WARNING __main__  stack.py loadHeader() line:167 -- Did not find header file /media/cudmore/data/richard/rr30a/naked-tif/rr30a_s0/rr30a_s0.json
2022-01-24 16:47:11,818   INFO __main__  stack.py __init__() line:84 -- Creating header
2022-01-24 16:47:11,818  ERROR pymapmanager.baseAnnotations  baseAnnotations.py load() line:122 -- Did not find annotation file: /media/cudmore/data/richard/rr30a/naked-tif/rr30a_s0/rr30a_s0_db2.txt
2022-01-24 16:47:11,819  ERROR pymapmanager.baseAnnotations  baseAnnotations.py load() line:122 -- Did not find annotation file: /media/cudmore/data/richard/rr30a/naked-tif/rr30a_s0/rr30a_s0_l.txt
2022-01-24 16:47:11,829   INFO __main__  stack.py _makeFolder() line:350 -- Making base folder at /media/cudmore/data/richard/rr30a/naked-tif/rr30a_s0
2022-01-24 16:47:11,829  ERROR pymapmanager.logger  logger.py handle_exception() line:88 -- Uncaught exception
Traceback (most recent call last):
  File "pymapmanager/stack.py", line 431, in <module>
    run()
  File "pymapmanager/stack.py", line 382, in run
    myStack.save()
  File "pymapmanager/stack.py", line 176, in save
    self.getLineAnnotations().save()
  File "/home/cudmore/Sites/PyMapManager/pymapmanager/baseAnnotations.py", line 138, in save
    file.write(myFancyHeader)
NameError: name 'myFancyHeader' is not defined
2022-01-24 16:47:39,983   INFO __main__  stack.py loadImages() line:201 -- Loaded tif data (70, 1024, 1024) from tif file: /media/cudmore/data/richard/rr30a/naked-tif/rr30a_s0_ch2.tif
2022-01-24 16:47:39,983  WARNING __main__  stack.py loadHeader() line:167 -- Did not find header file /media/cudmore/data/richard/rr30a/naked-tif/rr30a_s0/rr30a_s0.json
2022-01-24 16:47:39,983   INFO __main__  stack.py __init__() line:84 -- Creating header
2022-01-24 16:47:39,983  ERROR pymapmanager.baseAnnotations  baseAnnotations.py load() line:122 -- Did not find annotation file: /media/cudmore/data/richard/rr30a/naked-tif/rr30a_s0/rr30a_s0_db2.txt
2022-01-24 16:47:39,985  ERROR pymapmanager.logger  logger.py handle_exception() line:88 -- Uncaught exception
Traceback (most recent call last):
  File "pymapmanager/stack.py", line 431, in <module>
    run()
  File "pymapmanager/stack.py", line 367, in run
    myStack = stack(nakedPath)
  File "pymapmanager/stack.py", line 103, in __init__
    self.loadLines()
  File "pymapmanager/stack.py", line 269, in loadLines
    self._lines = pymapmanager.lineAnnotations.lineAnnotations(self._basePath)
  File "/home/cudmore/Sites/PyMapManager/pymapmanager/baseAnnotations.py", line 48, in __init__
    self._df = self.load()
  File "/home/cudmore/Sites/PyMapManager/pymapmanager/baseAnnotations.py", line 126, in load
    df = pd.read_csv(annotationPath, header=1, index_col=False)
  File "/home/cudmore/Sites/PyMapManager/mm_env/lib/python3.8/site-packages/pandas/util/_decorators.py", line 311, in wrapper
    return func(*args, **kwargs)
  File "/home/cudmore/Sites/PyMapManager/mm_env/lib/python3.8/site-packages/pandas/io/parsers/readers.py", line 586, in read_csv
    return _read(filepath_or_buffer, kwds)
  File "/home/cudmore/Sites/PyMapManager/mm_env/lib/python3.8/site-packages/pandas/io/parsers/readers.py", line 482, in _read
    parser = TextFileReader(filepath_or_buffer, **kwds)
  File "/home/cudmore/Sites/PyMapManager/mm_env/lib/python3.8/site-packages/pandas/io/parsers/readers.py", line 811, in __init__
    self._engine = self._make_engine(self.engine)
  File "/home/cudmore/Sites/PyMapManager/mm_env/lib/python3.8/site-packages/pandas/io/parsers/readers.py", line 1040, in _make_engine
    return mapping[engine](self.f, **self.options)  # type: ignore[call-arg]
  File "/home/cudmore/Sites/PyMapManager/mm_env/lib/python3.8/site-packages/pandas/io/parsers/c_parser_wrapper.py", line 69, in __init__
    self._reader = parsers.TextReader(self.handles.handle, **kwds)
  File "pandas/_libs/parsers.pyx", line 549, in pandas._libs.parsers.TextReader.__cinit__
pandas.errors.EmptyDataError: No columns to parse from file
2022-01-24 16:48:37,966   INFO __main__  stack.py loadImages() line:201 -- Loaded tif data (70, 1024, 1024) from tif file: /media/cudmore/data/richard/rr30a/naked-tif/rr30a_s0_ch2.tif
2022-01-24 16:48:37,966  WARNING __main__  stack.py loadHeader() line:167 -- Did not find header file /media/cudmore/data/richard/rr30a/naked-tif/rr30a_s0/rr30a_s0.json
2022-01-24 16:48:37,966   INFO __main__  stack.py __init__() line:84 -- Creating header
2022-01-24 16:48:37,966  ERROR pymapmanager.baseAnnotations  baseAnnotations.py load() line:122 -- Did not find annotation file: /media/cudmore/data/richard/rr30a/naked-tif/rr30a_s0/rr30a_s0_db2.txt
2022-01-24 16:48:37,968  ERROR pymapmanager.logger  logger.py handle_exception() line:88 -- Uncaught exception
Traceback (most recent call last):
  File "pymapmanager/stack.py", line 431, in <module>
    run()
  File "pymapmanager/stack.py", line 367, in run
    myStack = stack(nakedPath)
  File "pymapmanager/stack.py", line 103, in __init__
    self.loadLines()
  File "pymapmanager/stack.py", line 269, in loadLines
    self._lines = pymapmanager.lineAnnotations.lineAnnotations(self._basePath)
  File "/home/cudmore/Sites/PyMapManager/pymapmanager/baseAnnotations.py", line 48, in __init__
    self._df = self.load()
  File "/home/cudmore/Sites/PyMapManager/pymapmanager/baseAnnotations.py", line 126, in load
    df = pd.read_csv(annotationPath, header=1, index_col=False)
  File "/home/cudmore/Sites/PyMapManager/mm_env/lib/python3.8/site-packages/pandas/util/_decorators.py", line 311, in wrapper
    return func(*args, **kwargs)
  File "/home/cudmore/Sites/PyMapManager/mm_env/lib/python3.8/site-packages/pandas/io/parsers/readers.py", line 586, in read_csv
    return _read(filepath_or_buffer, kwds)
  File "/home/cudmore/Sites/PyMapManager/mm_env/lib/python3.8/site-packages/pandas/io/parsers/readers.py", line 482, in _read
    parser = TextFileReader(filepath_or_buffer, **kwds)
  File "/home/cudmore/Sites/PyMapManager/mm_env/lib/python3.8/site-packages/pandas/io/parsers/readers.py", line 811, in __init__
    self._engine = self._make_engine(self.engine)
  File "/home/cudmore/Sites/PyMapManager/mm_env/lib/python3.8/site-packages/pandas/io/parsers/readers.py", line 1040, in _make_engine
    return mapping[engine](self.f, **self.options)  # type: ignore[call-arg]
  File "/home/cudmore/Sites/PyMapManager/mm_env/lib/python3.8/site-packages/pandas/io/parsers/c_parser_wrapper.py", line 69, in __init__
    self._reader = parsers.TextReader(self.handles.handle, **kwds)
  File "pandas/_libs/parsers.pyx", line 549, in pandas._libs.parsers.TextReader.__cinit__
pandas.errors.EmptyDataError: No columns to parse from file
2022-01-24 16:48:51,532   INFO __main__  stack.py loadImages() line:201 -- Loaded tif data (70, 1024, 1024) from tif file: /media/cudmore/data/richard/rr30a/naked-tif/rr30a_s0_ch2.tif
2022-01-24 16:48:51,532  WARNING __main__  stack.py loadHeader() line:167 -- Did not find header file /media/cudmore/data/richard/rr30a/naked-tif/rr30a_s0/rr30a_s0.json
2022-01-24 16:48:51,532   INFO __main__  stack.py __init__() line:84 -- Creating header
2022-01-24 16:48:51,532  ERROR pymapmanager.baseAnnotations  baseAnnotations.py load() line:122 -- Did not find annotation file: /media/cudmore/data/richard/rr30a/naked-tif/rr30a_s0/rr30a_s0_db2.txt
2022-01-24 16:48:51,533  ERROR pymapmanager.baseAnnotations  baseAnnotations.py load() line:122 -- Did not find annotation file: /media/cudmore/data/richard/rr30a/naked-tif/rr30a_s0/rr30a_s0_l.txt
2022-01-24 16:48:51,544   INFO __main__  stack.py _makeFolder() line:347 -- Base folder already exists at /media/cudmore/data/richard/rr30a/naked-tif/rr30a_s0
2022-01-24 16:49:15,794   INFO __main__  stack.py loadImages() line:201 -- Loaded tif data (70, 1024, 1024) from tif file: /media/cudmore/data/richard/rr30a/naked-tif/rr30a_s0_ch2.tif
2022-01-24 16:49:15,794  WARNING __main__  stack.py loadHeader() line:167 -- Did not find header file /media/cudmore/data/richard/rr30a/naked-tif/rr30a_s0/rr30a_s0.json
2022-01-24 16:49:15,794   INFO __main__  stack.py __init__() line:84 -- Creating header
2022-01-24 16:49:15,796  ERROR pymapmanager.baseAnnotations  baseAnnotations.py load() line:122 -- Did not find annotation file: /media/cudmore/data/richard/rr30a/naked-tif/rr30a_s0/rr30a_s0_l.txt
2022-01-24 16:49:15,814   INFO __main__  stack.py _makeFolder() line:347 -- Base folder already exists at /media/cudmore/data/richard/rr30a/naked-tif/rr30a_s0
2022-01-24 16:51:58,352   INFO __main__  stack.py loadImages() line:201 -- Loaded tif data (70, 1024, 1024) from tif file: /media/cudmore/data/richard/rr30a/naked-tif/rr30a_s0_ch2.tif
2022-01-24 16:51:58,353  WARNING __main__  stack.py loadHeader() line:167 -- Did not find header file /media/cudmore/data/richard/rr30a/naked-tif/rr30a_s0/rr30a_s0.json
2022-01-24 16:51:58,353   INFO __main__  stack.py __init__() line:84 -- Creating header
2022-01-24 16:51:58,353  ERROR pymapmanager.baseAnnotations  baseAnnotations.py load() line:129 -- Did not find annotation file: /media/cudmore/data/richard/rr30a/naked-tif/rr30a_s0/rr30a_s0_db2.txt
2022-01-24 16:51:58,354  ERROR pymapmanager.baseAnnotations  baseAnnotations.py load() line:129 -- Did not find annotation file: /media/cudmore/data/richard/rr30a/naked-tif/rr30a_s0/rr30a_s0_l.txt
2022-01-24 16:51:58,358  ERROR pymapmanager.logger  logger.py handle_exception() line:88 -- Uncaught exception
Traceback (most recent call last):
  File "pymapmanager/stack.py", line 431, in <module>
    run()
  File "pymapmanager/stack.py", line 377, in run
    myStack.getPointAnnotations().addAnnotation(xPnt=10, yPnt=20, zPnt=30, roiType='spineROI')
  File "/home/cudmore/Sites/PyMapManager/pymapmanager/pointAnnotations.py", line 29, in addAnnotation
    thisRow = super(pointAnnotations, self).addAnnotation(*args,**kwargs)
  File "/home/cudmore/Sites/PyMapManager/pymapmanager/baseAnnotations.py", line 69, in addAnnotation
    self._df.loc[thisRow, 'cSeconds'] = time.now()
AttributeError: module 'time' has no attribute 'now'
2022-01-24 16:52:46,450   INFO __main__  stack.py loadImages() line:201 -- Loaded tif data (70, 1024, 1024) from tif file: /media/cudmore/data/richard/rr30a/naked-tif/rr30a_s0_ch2.tif
2022-01-24 16:52:46,450  WARNING __main__  stack.py loadHeader() line:167 -- Did not find header file /media/cudmore/data/richard/rr30a/naked-tif/rr30a_s0/rr30a_s0.json
2022-01-24 16:52:46,450   INFO __main__  stack.py __init__() line:84 -- Creating header
2022-01-24 16:52:46,450  ERROR pymapmanager.baseAnnotations  baseAnnotations.py load() line:129 -- Did not find annotation file: /media/cudmore/data/richard/rr30a/naked-tif/rr30a_s0/rr30a_s0_db2.txt
2022-01-24 16:52:46,452  ERROR pymapmanager.baseAnnotations  baseAnnotations.py load() line:129 -- Did not find annotation file: /media/cudmore/data/richard/rr30a/naked-tif/rr30a_s0/rr30a_s0_l.txt
2022-01-24 16:52:46,464   INFO __main__  stack.py _makeFolder() line:347 -- Base folder already exists at /media/cudmore/data/richard/rr30a/naked-tif/rr30a_s0
2022-01-24 16:54:01,973   INFO __main__  stack.py loadImages() line:201 -- Loaded tif data (70, 1024, 1024) from tif file: /media/cudmore/data/richard/rr30a/naked-tif/rr30a_s0_ch2.tif
2022-01-24 16:54:01,973  WARNING __main__  stack.py loadHeader() line:167 -- Did not find header file /media/cudmore/data/richard/rr30a/naked-tif/rr30a_s0/rr30a_s0.json
2022-01-24 16:54:01,973   INFO __main__  stack.py __init__() line:84 -- Creating header
2022-01-24 16:54:01,975  ERROR pymapmanager.baseAnnotations  baseAnnotations.py load() line:129 -- Did not find annotation file: /media/cudmore/data/richard/rr30a/naked-tif/rr30a_s0/rr30a_s0_l.txt
2022-01-24 16:54:01,995   INFO __main__  stack.py _makeFolder() line:347 -- Base folder already exists at /media/cudmore/data/richard/rr30a/naked-tif/rr30a_s0
2022-01-24 16:54:22,120   INFO __main__  stack.py loadImages() line:201 -- Loaded tif data (70, 1024, 1024) from tif file: /media/cudmore/data/richard/rr30a/naked-tif/rr30a_s0_ch2.tif
2022-01-24 16:54:22,120  WARNING __main__  stack.py loadHeader() line:167 -- Did not find header file /media/cudmore/data/richard/rr30a/naked-tif/rr30a_s0/rr30a_s0.json
2022-01-24 16:54:22,120   INFO __main__  stack.py __init__() line:84 -- Creating header
2022-01-24 16:54:22,122  ERROR pymapmanager.baseAnnotations  baseAnnotations.py load() line:129 -- Did not find annotation file: /media/cudmore/data/richard/rr30a/naked-tif/rr30a_s0/rr30a_s0_l.txt
2022-01-24 16:54:22,141   INFO __main__  stack.py _makeFolder() line:347 -- Base folder already exists at /media/cudmore/data/richard/rr30a/naked-tif/rr30a_s0
2022-01-24 16:55:03,181   INFO __main__  stack.py loadImages() line:201 -- Loaded tif data (70, 1024, 1024) from tif file: /media/cudmore/data/richard/rr30a/naked-tif/rr30a_s0_ch2.tif
2022-01-24 16:55:03,181  WARNING __main__  stack.py loadHeader() line:167 -- Did not find header file /media/cudmore/data/richard/rr30a/naked-tif/rr30a_s0/rr30a_s0.json
2022-01-24 16:55:03,181   INFO __main__  stack.py __init__() line:84 -- Creating header
2022-01-24 16:55:03,182  ERROR pymapmanager.baseAnnotations  baseAnnotations.py load() line:129 -- Did not find annotation file: /media/cudmore/data/richard/rr30a/naked-tif/rr30a_s0/rr30a_s0_db2.txt
2022-01-24 16:55:03,183  ERROR pymapmanager.baseAnnotations  baseAnnotations.py load() line:129 -- Did not find annotation file: /media/cudmore/data/richard/rr30a/naked-tif/rr30a_s0/rr30a_s0_l.txt
2022-01-24 16:55:03,195   INFO __main__  stack.py _makeFolder() line:347 -- Base folder already exists at /media/cudmore/data/richard/rr30a/naked-tif/rr30a_s0
2022-01-24 16:55:03,196  ERROR pymapmanager.logger  logger.py handle_exception() line:88 -- Uncaught exception
Traceback (most recent call last):
  File "pymapmanager/stack.py", line 431, in <module>
    run()
  File "pymapmanager/stack.py", line 382, in run
    myStack.save()
  File "pymapmanager/stack.py", line 177, in save
    self.getPointAnnotations().save()
  File "/home/cudmore/Sites/PyMapManager/pymapmanager/baseAnnotations.py", line 150, in save
    with open(annotationPath, 'r') as file:
FileNotFoundError: [Errno 2] No such file or directory: '/media/cudmore/data/richard/rr30a/naked-tif/rr30a_s0/rr30a_s0_db2.txt'
2022-01-24 16:55:38,992   INFO __main__  stack.py loadImages() line:201 -- Loaded tif data (70, 1024, 1024) from tif file: /media/cudmore/data/richard/rr30a/naked-tif/rr30a_s0_ch2.tif
2022-01-24 16:55:38,992  WARNING __main__  stack.py loadHeader() line:167 -- Did not find header file /media/cudmore/data/richard/rr30a/naked-tif/rr30a_s0/rr30a_s0.json
2022-01-24 16:55:38,992   INFO __main__  stack.py __init__() line:84 -- Creating header
2022-01-24 16:55:38,993  ERROR pymapmanager.baseAnnotations  baseAnnotations.py load() line:129 -- Did not find annotation file: /media/cudmore/data/richard/rr30a/naked-tif/rr30a_s0/rr30a_s0_db2.txt
2022-01-24 16:55:38,994  ERROR pymapmanager.baseAnnotations  baseAnnotations.py load() line:129 -- Did not find annotation file: /media/cudmore/data/richard/rr30a/naked-tif/rr30a_s0/rr30a_s0_l.txt
2022-01-24 16:55:39,005   INFO __main__  stack.py _makeFolder() line:347 -- Base folder already exists at /media/cudmore/data/richard/rr30a/naked-tif/rr30a_s0
2022-01-24 16:55:50,061   INFO __main__  stack.py loadImages() line:201 -- Loaded tif data (70, 1024, 1024) from tif file: /media/cudmore/data/richard/rr30a/naked-tif/rr30a_s0_ch2.tif
2022-01-24 16:55:50,062  WARNING __main__  stack.py loadHeader() line:167 -- Did not find header file /media/cudmore/data/richard/rr30a/naked-tif/rr30a_s0/rr30a_s0.json
2022-01-24 16:55:50,062   INFO __main__  stack.py __init__() line:84 -- Creating header
2022-01-24 16:55:50,064  ERROR pymapmanager.baseAnnotations  baseAnnotations.py load() line:129 -- Did not find annotation file: /media/cudmore/data/richard/rr30a/naked-tif/rr30a_s0/rr30a_s0_l.txt
2022-01-24 16:55:50,084   INFO __main__  stack.py _makeFolder() line:347 -- Base folder already exists at /media/cudmore/data/richard/rr30a/naked-tif/rr30a_s0
2022-01-24 16:56:02,806   INFO __main__  stack.py loadImages() line:201 -- Loaded tif data (70, 1024, 1024) from tif file: /media/cudmore/data/richard/rr30a/naked-tif/rr30a_s0_ch2.tif
2022-01-24 16:56:02,806  WARNING __main__  stack.py loadHeader() line:167 -- Did not find header file /media/cudmore/data/richard/rr30a/naked-tif/rr30a_s0/rr30a_s0.json
2022-01-24 16:56:02,806   INFO __main__  stack.py __init__() line:84 -- Creating header
2022-01-24 16:56:02,808  ERROR pymapmanager.baseAnnotations  baseAnnotations.py load() line:129 -- Did not find annotation file: /media/cudmore/data/richard/rr30a/naked-tif/rr30a_s0/rr30a_s0_l.txt
2022-01-24 16:56:02,828   INFO __main__  stack.py _makeFolder() line:347 -- Base folder already exists at /media/cudmore/data/richard/rr30a/naked-tif/rr30a_s0
2022-01-24 16:57:03,336   INFO __main__  stack.py loadImages() line:203 -- Loaded tif data (70, 1024, 1024) from tif file: /media/cudmore/data/richard/rr30a/naked-tif/rr30a_s0_ch2.tif
2022-01-24 16:57:03,336  WARNING __main__  stack.py loadHeader() line:167 -- Did not find header file /media/cudmore/data/richard/rr30a/naked-tif/rr30a_s0/rr30a_s0.json
2022-01-24 16:57:03,336   INFO __main__  stack.py __init__() line:84 -- Creating header
2022-01-24 16:57:03,338  ERROR pymapmanager.baseAnnotations  baseAnnotations.py load() line:129 -- Did not find annotation file: /media/cudmore/data/richard/rr30a/naked-tif/rr30a_s0/rr30a_s0_l.txt
2022-01-24 16:57:03,357   INFO __main__  stack.py _makeFolder() line:349 -- Base folder already exists at /media/cudmore/data/richard/rr30a/naked-tif/rr30a_s0
2022-01-24 16:57:03,357   INFO __main__  stack.py _makeFolder() line:349 -- Base folder already exists at /media/cudmore/data/richard/rr30a/naked-tif/rr30a_s0
2022-01-24 16:57:03,358   INFO __main__  stack.py saveHeader() line:157 -- Saved header /media/cudmore/data/richard/rr30a/naked-tif/rr30a_s0/rr30a_s0.json
2022-01-24 16:57:14,008   INFO __main__  stack.py loadImages() line:203 -- Loaded tif data (70, 1024, 1024) from tif file: /media/cudmore/data/richard/rr30a/naked-tif/rr30a_s0_ch2.tif
2022-01-24 16:57:14,008   INFO __main__  stack.py loadHeader() line:162 -- Loading header /media/cudmore/data/richard/rr30a/naked-tif/rr30a_s0/rr30a_s0.json
2022-01-24 16:57:14,010  ERROR pymapmanager.baseAnnotations  baseAnnotations.py load() line:129 -- Did not find annotation file: /media/cudmore/data/richard/rr30a/naked-tif/rr30a_s0/rr30a_s0_l.txt
2022-01-24 16:57:14,031   INFO __main__  stack.py _makeFolder() line:349 -- Base folder already exists at /media/cudmore/data/richard/rr30a/naked-tif/rr30a_s0
2022-01-24 16:57:14,031   INFO __main__  stack.py _makeFolder() line:349 -- Base folder already exists at /media/cudmore/data/richard/rr30a/naked-tif/rr30a_s0
2022-01-24 16:57:14,031   INFO __main__  stack.py saveHeader() line:157 -- Saved header /media/cudmore/data/richard/rr30a/naked-tif/rr30a_s0/rr30a_s0.json
